2025-08-31 17:25:33,549 [    749]   WARN - c.i.o.u.r.overrides - Conflicting registry key definition for key clion.wsl.sleep.timeout: it was defined by plugin com.intellij.nativeDebug but redefined by plugin com.jetbrains.rust. Consider adding overrides="true" for one of the plugins, see the documentation for com.intellij.openapi.util.registry.RegistryKeyBean.overrides for more details.
2025-08-31 17:25:37,816 [   5016]   WARN - #c.i.o.v.n.p.PersistentFSImpl - Can't find root[#90413] in persistence
2025-08-31 17:25:39,377 [   6577]   WARN - #c.i.s.c.i.StationSocketConnectionLoop - Discovery connection failed with NoSuchFileException (/run/user/1000/jb.station.sock)
2025-08-31 17:37:55,518 [ 742718]   WARN - #o.j.c.f.l.l.s.c.FullLineCompletionInputBuilder - LazyStandaloneCoroutine was cancelled
java.lang.Throwable: Control-flow exceptions (e.g. this class kotlinx.coroutines.JobCancellationException) should never be logged. Instead, these should have been rethrown if caught.
	at com.intellij.openapi.diagnostic.Logger.ensureNotControlFlow(Logger.java:503)
	at com.intellij.idea.IdeaLogger.warn(IdeaLogger.java:124)
	at com.intellij.openapi.diagnostic.Logger.warn(Logger.java:353)
	at org.jetbrains.completion.full.line.local.suggest.collector.FullLineCompletionInputBuilder.buildRecentContext(FullLineCompletionInputBuilder.kt:150)
	at org.jetbrains.completion.full.line.local.suggest.collector.FullLineCompletionInputBuilder.access$buildRecentContext(FullLineCompletionInputBuilder.kt:30)
	at org.jetbrains.completion.full.line.local.suggest.collector.FullLineCompletionInputBuilder$buildRecentContext$1.invokeSuspend(FullLineCompletionInputBuilder.kt)
	at kotlin.coroutines.jvm.internal.BaseContinuationImpl.resumeWith(ContinuationImpl.kt:33)
	at kotlinx.coroutines.UndispatchedCoroutine.afterResume(CoroutineContext.kt:277)
	at kotlinx.coroutines.AbstractCoroutine.resumeWith(AbstractCoroutine.kt:99)
	at kotlin.coroutines.jvm.internal.BaseContinuationImpl.resumeWith(ContinuationImpl.kt:46)
	at kotlinx.coroutines.DispatchedTask.run(DispatchedTask.kt:102)
	at kotlinx.coroutines.scheduling.CoroutineScheduler.runSafely(CoroutineScheduler.kt:608)
	at kotlinx.coroutines.scheduling.CoroutineScheduler$Worker.executeTask(CoroutineScheduler.kt:873)
	at kotlinx.coroutines.scheduling.CoroutineScheduler$Worker.runWorker(CoroutineScheduler.kt:763)
	at kotlinx.coroutines.scheduling.CoroutineScheduler$Worker.run(CoroutineScheduler.kt:750)
Caused by: kotlinx.coroutines.JobCancellationException: LazyStandaloneCoroutine was cancelled; job=LazyStandaloneCoroutine{Cancelling}@79bc4fbb
2025-08-31 17:37:59,258 [ 746458]   WARN - #o.j.c.f.l.l.s.c.FullLineCompletionInputBuilder - LazyStandaloneCoroutine was cancelled
java.lang.Throwable: Control-flow exceptions (e.g. this class kotlinx.coroutines.JobCancellationException) should never be logged. Instead, these should have been rethrown if caught.
	at com.intellij.openapi.diagnostic.Logger.ensureNotControlFlow(Logger.java:503)
	at com.intellij.idea.IdeaLogger.warn(IdeaLogger.java:124)
	at com.intellij.openapi.diagnostic.Logger.warn(Logger.java:353)
	at org.jetbrains.completion.full.line.local.suggest.collector.FullLineCompletionInputBuilder.buildRecentContext(FullLineCompletionInputBuilder.kt:150)
	at org.jetbrains.completion.full.line.local.suggest.collector.FullLineCompletionInputBuilder.access$buildRecentContext(FullLineCompletionInputBuilder.kt:30)
	at org.jetbrains.completion.full.line.local.suggest.collector.FullLineCompletionInputBuilder$buildRecentContext$1.invokeSuspend(FullLineCompletionInputBuilder.kt)
	at kotlin.coroutines.jvm.internal.BaseContinuationImpl.resumeWith(ContinuationImpl.kt:33)
	at kotlinx.coroutines.UndispatchedCoroutine.afterResume(CoroutineContext.kt:277)
	at kotlinx.coroutines.AbstractCoroutine.resumeWith(AbstractCoroutine.kt:99)
	at kotlin.coroutines.jvm.internal.BaseContinuationImpl.resumeWith(ContinuationImpl.kt:46)
	at kotlinx.coroutines.DispatchedTask.run(DispatchedTask.kt:102)
	at kotlinx.coroutines.scheduling.CoroutineScheduler.runSafely(CoroutineScheduler.kt:608)
	at kotlinx.coroutines.scheduling.CoroutineScheduler$Worker.executeTask(CoroutineScheduler.kt:873)
	at kotlinx.coroutines.scheduling.CoroutineScheduler$Worker.runWorker(CoroutineScheduler.kt:763)
	at kotlinx.coroutines.scheduling.CoroutineScheduler$Worker.run(CoroutineScheduler.kt:750)
Caused by: kotlinx.coroutines.JobCancellationException: LazyStandaloneCoroutine was cancelled; job=LazyStandaloneCoroutine{Cancelling}@5b5ab0d3
2025-08-31 17:38:02,986 [ 750186]   WARN - #o.j.c.f.l.i.p.d.a.n.NativeServerDiagnostic$Companion - 2025-08-31 15:38:02.986232 [flcc_grpc_inference_service.cpp:121:prefill] call ended, got an exception 'std::future_error: Broken promise' during execution

2025-08-31 17:38:03,117 [ 750317]   WARN - #o.j.c.f.l.i.p.d.a.n.NativeServerDiagnostic$Companion - 2025-08-31 15:38:03.117777 [flcc_grpc_inference_service.cpp:121:prefill] call ended, got an exception 'std::future_error: Broken promise' during execution

2025-08-31 17:38:03,994 [ 751194]   WARN - #o.j.c.f.l.i.p.d.a.n.NativeServerDiagnostic$Companion - 2025-08-31 15:38:03.994233 [flcc_grpc_inference_service.cpp:121:prefill] call ended, got an exception 'std::future_error: Broken promise' during execution

2025-08-31 17:38:04,788 [ 751988]   WARN - #o.j.c.f.l.l.s.c.FullLineCompletionInputBuilder - LazyStandaloneCoroutine was cancelled
java.lang.Throwable: Control-flow exceptions (e.g. this class kotlinx.coroutines.JobCancellationException) should never be logged. Instead, these should have been rethrown if caught.
	at com.intellij.openapi.diagnostic.Logger.ensureNotControlFlow(Logger.java:503)
	at com.intellij.idea.IdeaLogger.warn(IdeaLogger.java:124)
	at com.intellij.openapi.diagnostic.Logger.warn(Logger.java:353)
	at org.jetbrains.completion.full.line.local.suggest.collector.FullLineCompletionInputBuilder.buildRecentContext(FullLineCompletionInputBuilder.kt:150)
	at org.jetbrains.completion.full.line.local.suggest.collector.FullLineCompletionInputBuilder.access$buildRecentContext(FullLineCompletionInputBuilder.kt:30)
	at org.jetbrains.completion.full.line.local.suggest.collector.FullLineCompletionInputBuilder$buildRecentContext$1.invokeSuspend(FullLineCompletionInputBuilder.kt)
	at kotlin.coroutines.jvm.internal.BaseContinuationImpl.resumeWith(ContinuationImpl.kt:33)
	at kotlinx.coroutines.UndispatchedCoroutine.afterResume(CoroutineContext.kt:277)
	at kotlinx.coroutines.AbstractCoroutine.resumeWith(AbstractCoroutine.kt:99)
	at kotlin.coroutines.jvm.internal.BaseContinuationImpl.resumeWith(ContinuationImpl.kt:46)
	at kotlinx.coroutines.DispatchedTask.run(DispatchedTask.kt:102)
	at kotlinx.coroutines.scheduling.CoroutineScheduler.runSafely(CoroutineScheduler.kt:608)
	at kotlinx.coroutines.scheduling.CoroutineScheduler$Worker.executeTask(CoroutineScheduler.kt:873)
	at kotlinx.coroutines.scheduling.CoroutineScheduler$Worker.runWorker(CoroutineScheduler.kt:763)
	at kotlinx.coroutines.scheduling.CoroutineScheduler$Worker.run(CoroutineScheduler.kt:750)
Caused by: kotlinx.coroutines.JobCancellationException: LazyStandaloneCoroutine was cancelled; job=LazyStandaloneCoroutine{Cancelling}@6c90daa9
2025-08-31 17:38:05,556 [ 752756]   WARN - #o.j.c.f.l.i.p.d.a.n.NativeServerDiagnostic$Companion - 2025-08-31 15:38:05.556366 [flcc_grpc_inference_service.cpp:121:prefill] call ended, got an exception 'std::future_error: Broken promise' during execution

2025-08-31 17:38:05,728 [ 752928]   WARN - #o.j.c.f.l.l.s.c.FullLineCompletionInputBuilder - LazyStandaloneCoroutine was cancelled
java.lang.Throwable: Control-flow exceptions (e.g. this class kotlinx.coroutines.JobCancellationException) should never be logged. Instead, these should have been rethrown if caught.
	at com.intellij.openapi.diagnostic.Logger.ensureNotControlFlow(Logger.java:503)
	at com.intellij.idea.IdeaLogger.warn(IdeaLogger.java:124)
	at com.intellij.openapi.diagnostic.Logger.warn(Logger.java:353)
	at org.jetbrains.completion.full.line.local.suggest.collector.FullLineCompletionInputBuilder.buildRecentContext(FullLineCompletionInputBuilder.kt:150)
	at org.jetbrains.completion.full.line.local.suggest.collector.FullLineCompletionInputBuilder.access$buildRecentContext(FullLineCompletionInputBuilder.kt:30)
	at org.jetbrains.completion.full.line.local.suggest.collector.FullLineCompletionInputBuilder$buildRecentContext$1.invokeSuspend(FullLineCompletionInputBuilder.kt)
	at kotlin.coroutines.jvm.internal.BaseContinuationImpl.resumeWith(ContinuationImpl.kt:33)
	at kotlinx.coroutines.UndispatchedCoroutine.afterResume(CoroutineContext.kt:277)
	at kotlinx.coroutines.AbstractCoroutine.resumeWith(AbstractCoroutine.kt:99)
	at kotlin.coroutines.jvm.internal.BaseContinuationImpl.resumeWith(ContinuationImpl.kt:46)
	at kotlinx.coroutines.DispatchedTask.run(DispatchedTask.kt:102)
	at kotlinx.coroutines.scheduling.CoroutineScheduler.runSafely(CoroutineScheduler.kt:608)
	at kotlinx.coroutines.scheduling.CoroutineScheduler$Worker.executeTask(CoroutineScheduler.kt:873)
	at kotlinx.coroutines.scheduling.CoroutineScheduler$Worker.runWorker(CoroutineScheduler.kt:763)
	at kotlinx.coroutines.scheduling.CoroutineScheduler$Worker.run(CoroutineScheduler.kt:750)
Caused by: kotlinx.coroutines.JobCancellationException: LazyStandaloneCoroutine was cancelled; job=LazyStandaloneCoroutine{Cancelling}@d14ffaf
2025-08-31 17:38:05,817 [ 753017]   WARN - #o.j.c.f.l.i.p.d.a.n.NativeServerDiagnostic$Companion - 2025-08-31 15:38:05.817669 [flcc_grpc_inference_service.cpp:121:prefill] call ended, got an exception 'std::future_error: Broken promise' during execution

2025-08-31 17:38:06,793 [ 753993]   WARN - #o.j.c.f.l.i.p.d.a.n.NativeServerDiagnostic$Companion - 2025-08-31 15:38:06.793510 [flcc_grpc_inference_service.cpp:121:prefill] call ended, got an exception 'std::future_error: Broken promise' during execution

2025-08-31 17:38:07,145 [ 754345]   WARN - #o.j.c.f.l.i.p.d.a.n.NativeServerDiagnostic$Companion - 2025-08-31 15:38:07.145032 [flcc_grpc_inference_service.cpp:121:prefill] call ended, got an exception 'std::future_error: Broken promise' during execution

2025-08-31 17:38:07,444 [ 754644]   WARN - #o.j.c.f.l.i.p.d.a.n.NativeServerDiagnostic$Companion - 2025-08-31 15:38:07.444411 [flcc_grpc_inference_service.cpp:121:prefill] call ended, got an exception 'std::future_error: Broken promise' during execution

2025-08-31 17:38:19,158 [ 766358]   WARN - #o.j.c.f.l.l.s.c.FullLineCompletionInputBuilder - LazyStandaloneCoroutine was cancelled
java.lang.Throwable: Control-flow exceptions (e.g. this class kotlinx.coroutines.JobCancellationException) should never be logged. Instead, these should have been rethrown if caught.
	at com.intellij.openapi.diagnostic.Logger.ensureNotControlFlow(Logger.java:503)
	at com.intellij.idea.IdeaLogger.warn(IdeaLogger.java:124)
	at com.intellij.openapi.diagnostic.Logger.warn(Logger.java:353)
	at org.jetbrains.completion.full.line.local.suggest.collector.FullLineCompletionInputBuilder.buildRecentContext(FullLineCompletionInputBuilder.kt:150)
	at org.jetbrains.completion.full.line.local.suggest.collector.FullLineCompletionInputBuilder.access$buildRecentContext(FullLineCompletionInputBuilder.kt:30)
	at org.jetbrains.completion.full.line.local.suggest.collector.FullLineCompletionInputBuilder$buildRecentContext$1.invokeSuspend(FullLineCompletionInputBuilder.kt)
	at kotlin.coroutines.jvm.internal.BaseContinuationImpl.resumeWith(ContinuationImpl.kt:33)
	at kotlinx.coroutines.UndispatchedCoroutine.afterResume(CoroutineContext.kt:277)
	at kotlinx.coroutines.AbstractCoroutine.resumeWith(AbstractCoroutine.kt:99)
	at kotlin.coroutines.jvm.internal.BaseContinuationImpl.resumeWith(ContinuationImpl.kt:46)
	at kotlinx.coroutines.DispatchedTask.run(DispatchedTask.kt:102)
	at kotlinx.coroutines.scheduling.CoroutineScheduler.runSafely(CoroutineScheduler.kt:608)
	at kotlinx.coroutines.scheduling.CoroutineScheduler$Worker.executeTask(CoroutineScheduler.kt:873)
	at kotlinx.coroutines.scheduling.CoroutineScheduler$Worker.runWorker(CoroutineScheduler.kt:763)
	at kotlinx.coroutines.scheduling.CoroutineScheduler$Worker.run(CoroutineScheduler.kt:750)
Caused by: kotlinx.coroutines.JobCancellationException: LazyStandaloneCoroutine was cancelled; job=LazyStandaloneCoroutine{Cancelling}@22e4400b
2025-08-31 17:38:19,592 [ 766792]   WARN - #o.j.c.f.l.i.p.d.a.n.NativeServerDiagnostic$Companion - 2025-08-31 15:38:19.592882 [flcc_grpc_inference_service.cpp:121:prefill] call ended, got an exception 'std::future_error: Broken promise' during execution

2025-08-31 17:38:19,881 [ 767081]   WARN - #o.j.c.f.l.i.p.d.a.n.NativeServerDiagnostic$Companion - 2025-08-31 15:38:19.881796 [flcc_grpc_inference_service.cpp:121:prefill] call ended, got an exception 'std::future_error: Broken promise' during execution

2025-08-31 17:38:20,048 [ 767248]   WARN - #o.j.c.f.l.i.p.d.a.n.NativeServerDiagnostic$Companion - 2025-08-31 15:38:20.48553 [flcc_grpc_inference_service.cpp:121:prefill] call ended, got an exception 'std::future_error: Broken promise' during execution

2025-08-31 17:38:20,174 [ 767374]   WARN - #o.j.c.f.l.i.p.d.a.n.NativeServerDiagnostic$Companion - 2025-08-31 15:38:20.174101 [flcc_grpc_inference_service.cpp:121:prefill] call ended, got an exception 'std::future_error: Broken promise' during execution

2025-08-31 17:38:20,303 [ 767503]   WARN - #o.j.c.f.l.i.p.d.a.n.NativeServerDiagnostic$Companion - 2025-08-31 15:38:20.303128 [flcc_grpc_inference_service.cpp:121:prefill] call ended, got an exception 'std::future_error: Broken promise' during execution

2025-08-31 17:38:20,589 [ 767789]   WARN - #o.j.c.f.l.i.p.d.a.n.NativeServerDiagnostic$Companion - 2025-08-31 15:38:20.589821 [flcc_grpc_inference_service.cpp:121:prefill] call ended, got an exception 'std::future_error: Broken promise' during execution

2025-08-31 17:38:21,404 [ 768604]   WARN - #o.j.c.f.l.i.p.d.a.n.NativeServerDiagnostic$Companion - 2025-08-31 15:38:21.404861 [flcc_grpc_inference_service.cpp:121:prefill] call ended, got an exception 'std::future_error: Broken promise' during execution

2025-08-31 17:44:12,147 [1119347]   WARN - #o.j.c.f.l.l.s.c.FullLineCompletionInputBuilder - LazyStandaloneCoroutine was cancelled
java.lang.Throwable: Control-flow exceptions (e.g. this class kotlinx.coroutines.JobCancellationException) should never be logged. Instead, these should have been rethrown if caught.
	at com.intellij.openapi.diagnostic.Logger.ensureNotControlFlow(Logger.java:503)
	at com.intellij.idea.IdeaLogger.warn(IdeaLogger.java:124)
	at com.intellij.openapi.diagnostic.Logger.warn(Logger.java:353)
	at org.jetbrains.completion.full.line.local.suggest.collector.FullLineCompletionInputBuilder.buildRecentContext(FullLineCompletionInputBuilder.kt:150)
	at org.jetbrains.completion.full.line.local.suggest.collector.FullLineCompletionInputBuilder.access$buildRecentContext(FullLineCompletionInputBuilder.kt:30)
	at org.jetbrains.completion.full.line.local.suggest.collector.FullLineCompletionInputBuilder$buildRecentContext$1.invokeSuspend(FullLineCompletionInputBuilder.kt)
	at kotlin.coroutines.jvm.internal.BaseContinuationImpl.resumeWith(ContinuationImpl.kt:33)
	at kotlinx.coroutines.UndispatchedCoroutine.afterResume(CoroutineContext.kt:277)
	at kotlinx.coroutines.AbstractCoroutine.resumeWith(AbstractCoroutine.kt:99)
	at kotlin.coroutines.jvm.internal.BaseContinuationImpl.resumeWith(ContinuationImpl.kt:46)
	at kotlinx.coroutines.DispatchedTask.run(DispatchedTask.kt:102)
	at kotlinx.coroutines.scheduling.CoroutineScheduler.runSafely(CoroutineScheduler.kt:608)
	at kotlinx.coroutines.scheduling.CoroutineScheduler$Worker.executeTask(CoroutineScheduler.kt:873)
	at kotlinx.coroutines.scheduling.CoroutineScheduler$Worker.runWorker(CoroutineScheduler.kt:763)
	at kotlinx.coroutines.scheduling.CoroutineScheduler$Worker.run(CoroutineScheduler.kt:750)
Caused by: kotlinx.coroutines.JobCancellationException: LazyStandaloneCoroutine was cancelled; job=LazyStandaloneCoroutine{Cancelling}@108971b9
2025-08-31 17:45:12,523 [1179723]   WARN - #o.j.c.f.l.i.p.d.a.n.NativeServerDiagnostic$Companion - 2025-08-31 15:45:12.523517 [flcc_grpc_inference_service.cpp:121:prefill] call ended, got an exception 'std::future_error: Broken promise' during execution

2025-08-31 17:45:13,022 [1180222]   WARN - #o.j.c.f.l.l.s.c.FullLineCompletionInputBuilder - LazyStandaloneCoroutine was cancelled
java.lang.Throwable: Control-flow exceptions (e.g. this class kotlinx.coroutines.JobCancellationException) should never be logged. Instead, these should have been rethrown if caught.
	at com.intellij.openapi.diagnostic.Logger.ensureNotControlFlow(Logger.java:503)
	at com.intellij.idea.IdeaLogger.warn(IdeaLogger.java:124)
	at com.intellij.openapi.diagnostic.Logger.warn(Logger.java:353)
	at org.jetbrains.completion.full.line.local.suggest.collector.FullLineCompletionInputBuilder.buildRecentContext(FullLineCompletionInputBuilder.kt:150)
	at org.jetbrains.completion.full.line.local.suggest.collector.FullLineCompletionInputBuilder.access$buildRecentContext(FullLineCompletionInputBuilder.kt:30)
	at org.jetbrains.completion.full.line.local.suggest.collector.FullLineCompletionInputBuilder$buildRecentContext$1.invokeSuspend(FullLineCompletionInputBuilder.kt)
	at kotlin.coroutines.jvm.internal.BaseContinuationImpl.resumeWith(ContinuationImpl.kt:33)
	at kotlinx.coroutines.UndispatchedCoroutine.afterResume(CoroutineContext.kt:277)
	at kotlinx.coroutines.AbstractCoroutine.resumeWith(AbstractCoroutine.kt:99)
	at kotlin.coroutines.jvm.internal.BaseContinuationImpl.resumeWith(ContinuationImpl.kt:46)
	at kotlinx.coroutines.DispatchedTask.run(DispatchedTask.kt:102)
	at kotlinx.coroutines.scheduling.CoroutineScheduler.runSafely(CoroutineScheduler.kt:608)
	at kotlinx.coroutines.scheduling.CoroutineScheduler$Worker.executeTask(CoroutineScheduler.kt:873)
	at kotlinx.coroutines.scheduling.CoroutineScheduler$Worker.runWorker(CoroutineScheduler.kt:763)
	at kotlinx.coroutines.scheduling.CoroutineScheduler$Worker.run(CoroutineScheduler.kt:750)
Caused by: kotlinx.coroutines.JobCancellationException: LazyStandaloneCoroutine was cancelled; job=LazyStandaloneCoroutine{Cancelling}@4053db39
2025-08-31 17:45:13,164 [1180364]   WARN - #o.j.c.f.l.i.p.d.a.n.NativeServerDiagnostic$Companion - 2025-08-31 15:45:13.164752 [flcc_grpc_inference_service.cpp:121:prefill] call ended, got an exception 'std::future_error: Broken promise' during execution

2025-08-31 17:45:13,353 [1180553]   WARN - #o.j.c.f.l.i.p.d.a.n.NativeServerDiagnostic$Companion - 2025-08-31 15:45:13.353084 [flcc_grpc_inference_service.cpp:121:prefill] call ended, got an exception 'std::future_error: Broken promise' during execution

2025-08-31 17:45:13,536 [1180736]   WARN - #o.j.c.f.l.i.p.d.a.n.NativeServerDiagnostic$Companion - 2025-08-31 15:45:13.536605 [flcc_grpc_inference_service.cpp:121:prefill] call ended, got an exception 'std::future_error: Broken promise' during execution

2025-08-31 17:45:13,769 [1180969]   WARN - #o.j.c.f.l.i.p.d.a.n.NativeServerDiagnostic$Companion - 2025-08-31 15:45:13.769281 [flcc_grpc_inference_service.cpp:121:prefill] call ended, got an exception 'std::future_error: Broken promise' during execution

2025-08-31 17:45:14,408 [1181608]   WARN - #o.j.c.f.l.i.p.d.a.n.NativeServerDiagnostic$Companion - 2025-08-31 15:45:14.408135 [flcc_grpc_inference_service.cpp:121:prefill] call ended, got an exception 'std::future_error: Broken promise' during execution

2025-08-31 17:45:30,244 [1197444]   WARN - #o.j.c.f.l.i.p.d.a.n.NativeServerDiagnostic$Companion - 2025-08-31
2025-08-31 17:45:30,244 [1197444]   WARN - #o.j.c.f.l.i.p.d.a.n.NativeServerDiagnostic$Companion -  15:45:30.244701 [flcc_grpc_inference_service.cpp:121:prefill] call ended, got an exception 'std::future_error: Broken promise' during execution

2025-08-31 17:45:31,006 [1198206]   WARN - #o.j.c.f.l.i.p.d.a.n.NativeServerDiagnostic$Companion - 2025-08-31 15:45:31.6380 [flcc_grpc_inference_service.cpp:121:prefill] call ended, got an exception 'std::future_error: Broken promise' during execution

2025-08-31 17:45:31,266 [1198466]   WARN - #o.j.c.f.l.i.p.d.a.n.NativeServerDiagnostic$Companion - 2025-08-31 15:45:31.266796 [flcc_grpc_inference_service.cpp:121:prefill] call ended, got an exception 'std::future_error: Broken promise' during execution

2025-08-31 17:45:31,412 [1198612]   WARN - #o.j.c.f.l.i.p.d.a.n.NativeServerDiagnostic$Companion - 2025-08-31 15:45:31.412646 [flcc_grpc_inference_service.cpp:121:prefill] call ended, got an exception 'std::future_error: Broken promise' during execution

2025-08-31 17:45:31,574 [1198774]   WARN - #o.j.c.f.l.i.p.d.a.n.NativeServerDiagnostic$Companion - 2025-08-31 15:45:31.574780 [flcc_grpc_inference_service.cpp:121:prefill] call ended, got an exception 'std::future_error: Broken promise' during execution

2025-08-31 17:45:56,781 [1223981]   WARN - #c.i.o.v.i.h.RemoteFileInfoImpl - Virtual local file not found for /home/jostsmrt/.cache/JetBrains/RustRover2025.1/httpFileSystem/catalog.json
2025-08-31 17:46:10,740 [1237940]   WARN - #o.j.c.f.l.i.p.d.a.n.NativeServerDiagnostic$Companion - 2025-08-31 15:46:10.740598 [flcc_grpc_inference_service.cpp:121:prefill] call ended, got an exception 'std::future_error: Broken promise' during execution

2025-08-31 17:46:10,901 [1238101]   WARN - #o.j.c.f.l.i.p.d.a.n.NativeServerDiagnostic$Companion - 2025-08-31 15:46:10.901919 [flcc_grpc_inference_service.cpp:121:prefill] call ended, got an exception 'std::future_error: Broken promise' during execution

2025-08-31 17:46:36,144 [1263344]   WARN - #o.j.c.f.l.l.s.c.FullLineCompletionInputBuilder - LazyStandaloneCoroutine was cancelled
java.lang.Throwable: Control-flow exceptions (e.g. this class kotlinx.coroutines.JobCancellationException) should never be logged. Instead, these should have been rethrown if caught.
	at com.intellij.openapi.diagnostic.Logger.ensureNotControlFlow(Logger.java:503)
	at com.intellij.idea.IdeaLogger.warn(IdeaLogger.java:124)
	at com.intellij.openapi.diagnostic.Logger.warn(Logger.java:353)
	at org.jetbrains.completion.full.line.local.suggest.collector.FullLineCompletionInputBuilder.buildRecentContext(FullLineCompletionInputBuilder.kt:150)
	at org.jetbrains.completion.full.line.local.suggest.collector.FullLineCompletionInputBuilder.access$buildRecentContext(FullLineCompletionInputBuilder.kt:30)
	at org.jetbrains.completion.full.line.local.suggest.collector.FullLineCompletionInputBuilder$buildRecentContext$1.invokeSuspend(FullLineCompletionInputBuilder.kt)
	at kotlin.coroutines.jvm.internal.BaseContinuationImpl.resumeWith(ContinuationImpl.kt:33)
	at kotlinx.coroutines.UndispatchedCoroutine.afterResume(CoroutineContext.kt:277)
	at kotlinx.coroutines.AbstractCoroutine.resumeWith(AbstractCoroutine.kt:99)
	at kotlin.coroutines.jvm.internal.BaseContinuationImpl.resumeWith(ContinuationImpl.kt:46)
	at kotlinx.coroutines.DispatchedTask.run(DispatchedTask.kt:102)
	at kotlinx.coroutines.scheduling.CoroutineScheduler.runSafely(CoroutineScheduler.kt:608)
	at kotlinx.coroutines.scheduling.CoroutineScheduler$Worker.executeTask(CoroutineScheduler.kt:873)
	at kotlinx.coroutines.scheduling.CoroutineScheduler$Worker.runWorker(CoroutineScheduler.kt:763)
	at kotlinx.coroutines.scheduling.CoroutineScheduler$Worker.run(CoroutineScheduler.kt:750)
Caused by: kotlinx.coroutines.JobCancellationException: LazyStandaloneCoroutine was cancelled; job=LazyStandaloneCoroutine{Cancelling}@70ea38f1
2025-08-31 17:46:36,821 [1264021]   WARN - #o.j.c.f.l.i.p.d.a.n.NativeServerDiagnostic$Companion - 2025-08-31 15:46:36.821200 [flcc_grpc_inference_service.cpp:121:prefill] call ended, got an exception 'std::future_error: Broken promise' during execution

2025-08-31 17:46:38,293 [1265493]   WARN - #o.j.c.f.l.i.p.d.a.n.NativeServerDiagnostic$Companion - 2025-08-31 15:46:38.293686 [flcc_grpc_inference_service.cpp:121:prefill] call ended, got an exception 'std::future_error: Broken promise' during execution

2025-08-31 17:49:22,011 [1429211]   WARN - #o.j.c.f.l.i.p.d.a.n.NativeServerDiagnostic$Companion - 2025-08-31 15:49:22.11616 [flcc_grpc_inference_service.cpp:121:prefill] call ended, got an exception 'std::future_error: Broken promise' during execution

2025-08-31 17:49:23,621 [1430821]   WARN - #o.j.c.f.l.i.p.d.a.n.NativeServerDiagnostic$Companion - 2025-08-31 15:49:23.621698 [flcc_grpc_inference_service.cpp:121:prefill] call ended, got an exception 'std::future_error: Broken promise' during execution

2025-08-31 18:00:42,830 [2110030]   WARN - #o.j.c.f.l.l.s.c.FullLineCompletionInputBuilder - LazyStandaloneCoroutine was cancelled
java.lang.Throwable: Control-flow exceptions (e.g. this class kotlinx.coroutines.JobCancellationException) should never be logged. Instead, these should have been rethrown if caught.
	at com.intellij.openapi.diagnostic.Logger.ensureNotControlFlow(Logger.java:503)
	at com.intellij.idea.IdeaLogger.warn(IdeaLogger.java:124)
	at com.intellij.openapi.diagnostic.Logger.warn(Logger.java:353)
	at org.jetbrains.completion.full.line.local.suggest.collector.FullLineCompletionInputBuilder.buildRecentContext(FullLineCompletionInputBuilder.kt:150)
	at org.jetbrains.completion.full.line.local.suggest.collector.FullLineCompletionInputBuilder.access$buildRecentContext(FullLineCompletionInputBuilder.kt:30)
	at org.jetbrains.completion.full.line.local.suggest.collector.FullLineCompletionInputBuilder$buildRecentContext$1.invokeSuspend(FullLineCompletionInputBuilder.kt)
	at kotlin.coroutines.jvm.internal.BaseContinuationImpl.resumeWith(ContinuationImpl.kt:33)
	at kotlinx.coroutines.UndispatchedCoroutine.afterResume(CoroutineContext.kt:277)
	at kotlinx.coroutines.AbstractCoroutine.resumeWith(AbstractCoroutine.kt:99)
	at kotlin.coroutines.jvm.internal.BaseContinuationImpl.resumeWith(ContinuationImpl.kt:46)
	at kotlinx.coroutines.DispatchedTask.run(DispatchedTask.kt:102)
	at kotlinx.coroutines.scheduling.CoroutineScheduler.runSafely(CoroutineScheduler.kt:608)
	at kotlinx.coroutines.scheduling.CoroutineScheduler$Worker.executeTask(CoroutineScheduler.kt:873)
	at kotlinx.coroutines.scheduling.CoroutineScheduler$Worker.runWorker(CoroutineScheduler.kt:763)
	at kotlinx.coroutines.scheduling.CoroutineScheduler$Worker.run(CoroutineScheduler.kt:750)
Caused by: kotlinx.coroutines.JobCancellationException: LazyStandaloneCoroutine was cancelled; job=LazyStandaloneCoroutine{Cancelling}@5f7342f8
2025-08-31 18:00:43,328 [2110528]   WARN - #o.j.c.f.l.i.p.d.a.n.NativeServerDiagnostic$Companion - 2025-08-31 16:00:43.328274 [flcc_grpc_inference_service.cpp:121:prefill] call ended, got an exception 'std::future_error: Broken promise' during execution

2025-08-31 18:00:44,743 [2111943]   WARN - #o.j.c.f.l.i.p.d.a.n.NativeServerDiagnostic$Companion - 2025-08-31 16:00:44.743161 [flcc_grpc_inference_service.cpp:121:prefill] call ended, got an exception 'std::future_error: Broken promise' during execution

2025-08-31 18:00:55,002 [2122202]   WARN - #o.j.c.f.l.l.s.c.FullLineCompletionInputBuilder - LazyStandaloneCoroutine was cancelled
java.lang.Throwable: Control-flow exceptions (e.g. this class kotlinx.coroutines.JobCancellationException) should never be logged. Instead, these should have been rethrown if caught.
	at com.intellij.openapi.diagnostic.Logger.ensureNotControlFlow(Logger.java:503)
	at com.intellij.idea.IdeaLogger.warn(IdeaLogger.java:124)
	at com.intellij.openapi.diagnostic.Logger.warn(Logger.java:353)
	at org.jetbrains.completion.full.line.local.suggest.collector.FullLineCompletionInputBuilder.buildRecentContext(FullLineCompletionInputBuilder.kt:150)
	at org.jetbrains.completion.full.line.local.suggest.collector.FullLineCompletionInputBuilder.access$buildRecentContext(FullLineCompletionInputBuilder.kt:30)
	at org.jetbrains.completion.full.line.local.suggest.collector.FullLineCompletionInputBuilder$buildRecentContext$1.invokeSuspend(FullLineCompletionInputBuilder.kt)
	at kotlin.coroutines.jvm.internal.BaseContinuationImpl.resumeWith(ContinuationImpl.kt:33)
	at kotlinx.coroutines.UndispatchedCoroutine.afterResume(CoroutineContext.kt:277)
	at kotlinx.coroutines.AbstractCoroutine.resumeWith(AbstractCoroutine.kt:99)
	at kotlin.coroutines.jvm.internal.BaseContinuationImpl.resumeWith(ContinuationImpl.kt:46)
	at kotlinx.coroutines.DispatchedTask.run(DispatchedTask.kt:102)
	at kotlinx.coroutines.scheduling.CoroutineScheduler.runSafely(CoroutineScheduler.kt:608)
	at kotlinx.coroutines.scheduling.CoroutineScheduler$Worker.executeTask(CoroutineScheduler.kt:873)
	at kotlinx.coroutines.scheduling.CoroutineScheduler$Worker.runWorker(CoroutineScheduler.kt:763)
	at kotlinx.coroutines.scheduling.CoroutineScheduler$Worker.run(CoroutineScheduler.kt:750)
Caused by: kotlinx.coroutines.JobCancellationException: LazyStandaloneCoroutine was cancelled; job=LazyStandaloneCoroutine{Cancelling}@c87d03e
2025-08-31 18:00:56,676 [2123876]   WARN - #o.j.c.f.l.i.p.d.a.n.NativeServerDiagnostic$Companion - 2025-08-31 16:00:56.676911 [flcc_grpc_inference_service.cpp:121:prefill] call ended, got an exception 'std::future_error: Broken promise' during execution

2025-08-31 18:00:56,857 [2124057]   WARN - #o.j.c.f.l.i.p.d.a.n.NativeServerDiagnostic$Companion - 2025-08-31 16:00:56.857378 [flcc_grpc_inference_service.cpp:121:prefill] call ended, got an exception 'std::future_error: Broken promise' during execution

2025-08-31 18:00:56,981 [2124181]   WARN - #o.j.c.f.l.i.p.d.a.n.NativeServerDiagnostic$Companion - 2025-08-31 16:00:56.981296 [flcc_grpc_inference_service.cpp:121:prefill] call ended, got an exception 'std::future_error: Broken promise' during execution

2025-08-31 18:00:57,083 [2124283]   WARN - #o.j.c.f.l.i.p.d.a.n.NativeServerDiagnostic$Companion - 2025-08-31 16:00:57.83854 [flcc_grpc_inference_service.cpp:121:prefill] call ended, got an exception 'std::future_error: Broken promise' during execution

2025-08-31 18:00:58,442 [2125642]   WARN - #o.j.c.f.l.i.p.d.a.n.NativeServerDiagnostic$Companion - 2025-08-31 16:00:58.441957 [flcc_grpc_inference_service.cpp:121:prefill] call ended, got an exception 'std::future_error: Broken promise' during execution

2025-08-31 18:00:58,556 [2125756]   WARN - #o.j.c.f.l.i.p.d.a.n.NativeServerDiagnostic$Companion - 2025-08-31 16:00:58.556384 [flcc_grpc_inference_service.cpp:121:prefill] call ended, got an exception 'std::future_error: Broken promise' during execution

2025-08-31 18:00:58,720 [2125920]   WARN - #o.j.c.f.l.i.p.d.a.n.NativeServerDiagnostic$Companion - 2025-08-31 16:00:58.720376 [flcc_grpc_inference_service.cpp:121:prefill] call ended, got an exception 'std::future_error: Broken promise' during execution

2025-08-31 18:00:59,129 [2126329]   WARN - #o.j.c.f.l.i.p.d.a.n.NativeServerDiagnostic$Companion - 2025-08-31 16:00:59.129873 [flcc_grpc_inference_service.cpp:121:prefill] call ended, got an exception 'std::future_error: Broken promise' during execution

2025-08-31 18:00:59,235 [2126435]   WARN - #o.j.c.f.l.i.p.d.a.n.NativeServerDiagnostic$Companion - 2025-08-31 16:00:59.235518 [flcc_grpc_inference_service.cpp:121:prefill] call ended, got an exception 'std::future_error: Broken promise' during execution

2025-08-31 18:00:59,399 [2126599]   WARN - #o.j.c.f.l.i.p.d.a.n.NativeServerDiagnostic$Companion - 2025-08-31 16:00:59.399674 [flcc_grpc_inference_service.cpp:121:prefill] call ended, got an exception 'std::future_error: Broken promise' during execution

2025-08-31 18:02:38,004 [2225204]   WARN - #o.j.c.f.l.l.s.c.FullLineCompletionInputBuilder - LazyStandaloneCoroutine was cancelled
java.lang.Throwable: Control-flow exceptions (e.g. this class kotlinx.coroutines.JobCancellationException) should never be logged. Instead, these should have been rethrown if caught.
	at com.intellij.openapi.diagnostic.Logger.ensureNotControlFlow(Logger.java:503)
	at com.intellij.idea.IdeaLogger.warn(IdeaLogger.java:124)
	at com.intellij.openapi.diagnostic.Logger.warn(Logger.java:353)
	at org.jetbrains.completion.full.line.local.suggest.collector.FullLineCompletionInputBuilder.buildRecentContext(FullLineCompletionInputBuilder.kt:150)
	at org.jetbrains.completion.full.line.local.suggest.collector.FullLineCompletionInputBuilder.access$buildRecentContext(FullLineCompletionInputBuilder.kt:30)
	at org.jetbrains.completion.full.line.local.suggest.collector.FullLineCompletionInputBuilder$buildRecentContext$1.invokeSuspend(FullLineCompletionInputBuilder.kt)
	at kotlin.coroutines.jvm.internal.BaseContinuationImpl.resumeWith(ContinuationImpl.kt:33)
	at kotlinx.coroutines.UndispatchedCoroutine.afterResume(CoroutineContext.kt:277)
	at kotlinx.coroutines.AbstractCoroutine.resumeWith(AbstractCoroutine.kt:99)
	at kotlin.coroutines.jvm.internal.BaseContinuationImpl.resumeWith(ContinuationImpl.kt:46)
	at kotlinx.coroutines.DispatchedTask.run(DispatchedTask.kt:102)
	at kotlinx.coroutines.scheduling.CoroutineScheduler.runSafely(CoroutineScheduler.kt:608)
	at kotlinx.coroutines.scheduling.CoroutineScheduler$Worker.executeTask(CoroutineScheduler.kt:873)
	at kotlinx.coroutines.scheduling.CoroutineScheduler$Worker.runWorker(CoroutineScheduler.kt:763)
	at kotlinx.coroutines.scheduling.CoroutineScheduler$Worker.run(CoroutineScheduler.kt:750)
Caused by: kotlinx.coroutines.JobCancellationException: LazyStandaloneCoroutine was cancelled; job=LazyStandaloneCoroutine{Cancelling}@38d164bf
2025-08-31 18:02:38,699 [2225899]   WARN - #o.j.c.f.l.i.p.d.a.n.NativeServerDiagnostic$Companion - 2025-08-31 16:02:38.699382 [flcc_grpc_inference_service.cpp:121:prefill] call ended, got an exception 'std::future_error: Broken promise' during execution

2025-08-31 18:02:38,816 [2226016]   WARN - #o.j.c.f.l.l.s.c.FullLineCompletionInputBuilder - LazyStandaloneCoroutine was cancelled
java.lang.Throwable: Control-flow exceptions (e.g. this class kotlinx.coroutines.JobCancellationException) should never be logged. Instead, these should have been rethrown if caught.
	at com.intellij.openapi.diagnostic.Logger.ensureNotControlFlow(Logger.java:503)
	at com.intellij.idea.IdeaLogger.warn(IdeaLogger.java:124)
	at com.intellij.openapi.diagnostic.Logger.warn(Logger.java:353)
	at org.jetbrains.completion.full.line.local.suggest.collector.FullLineCompletionInputBuilder.buildRecentContext(FullLineCompletionInputBuilder.kt:150)
	at org.jetbrains.completion.full.line.local.suggest.collector.FullLineCompletionInputBuilder.access$buildRecentContext(FullLineCompletionInputBuilder.kt:30)
	at org.jetbrains.completion.full.line.local.suggest.collector.FullLineCompletionInputBuilder$buildRecentContext$1.invokeSuspend(FullLineCompletionInputBuilder.kt)
	at kotlin.coroutines.jvm.internal.BaseContinuationImpl.resumeWith(ContinuationImpl.kt:33)
	at kotlinx.coroutines.UndispatchedCoroutine.afterResume(CoroutineContext.kt:277)
	at kotlinx.coroutines.AbstractCoroutine.resumeWith(AbstractCoroutine.kt:99)
	at kotlin.coroutines.jvm.internal.BaseContinuationImpl.resumeWith(ContinuationImpl.kt:46)
	at kotlinx.coroutines.DispatchedTask.run(DispatchedTask.kt:102)
	at kotlinx.coroutines.scheduling.CoroutineScheduler.runSafely(CoroutineScheduler.kt:608)
	at kotlinx.coroutines.scheduling.CoroutineScheduler$Worker.executeTask(CoroutineScheduler.kt:873)
	at kotlinx.coroutines.scheduling.CoroutineScheduler$Worker.runWorker(CoroutineScheduler.kt:763)
	at kotlinx.coroutines.scheduling.CoroutineScheduler$Worker.run(CoroutineScheduler.kt:750)
Caused by: kotlinx.coroutines.JobCancellationException: LazyStandaloneCoroutine was cancelled; job=LazyStandaloneCoroutine{Cancelling}@4578e2ac
2025-08-31 18:02:38,900 [2226100]   WARN - #o.j.c.f.l.i.p.d.a.n.NativeServerDiagnostic$Companion - 2025-08-31 16:02:38.900096 [flcc_grpc_inference_service.cpp:121:prefill] call ended, got an exception 'std::future_error: Broken promise' during execution

2025-08-31 18:02:40,008 [2227208]   WARN - #o.j.c.f.l.i.p.d.a.n.NativeServerDiagnostic$Companion - 2025-08-31 16:02:40.8483 [flcc_grpc_inference_service.cpp:121:prefill] call ended, got an exception 'std::future_error: Broken promise' during execution

2025-08-31 18:03:17,744 [2264944]   WARN - #o.j.c.f.l.i.p.d.a.n.NativeServerDiagnostic$Companion - 2025-08-31 16:03:17.744643 [flcc_grpc_inference_service.cpp:121:prefill] call ended, got an exception 'std::future_error: Broken promise' during execution

2025-08-31 18:04:21,179 [2328379]   WARN - #o.j.c.f.l.l.s.c.FullLineCompletionInputBuilder - LazyStandaloneCoroutine was cancelled
java.lang.Throwable: Control-flow exceptions (e.g. this class kotlinx.coroutines.JobCancellationException) should never be logged. Instead, these should have been rethrown if caught.
	at com.intellij.openapi.diagnostic.Logger.ensureNotControlFlow(Logger.java:503)
	at com.intellij.idea.IdeaLogger.warn(IdeaLogger.java:124)
	at com.intellij.openapi.diagnostic.Logger.warn(Logger.java:353)
	at org.jetbrains.completion.full.line.local.suggest.collector.FullLineCompletionInputBuilder.buildRecentContext(FullLineCompletionInputBuilder.kt:150)
	at org.jetbrains.completion.full.line.local.suggest.collector.FullLineCompletionInputBuilder.access$buildRecentContext(FullLineCompletionInputBuilder.kt:30)
	at org.jetbrains.completion.full.line.local.suggest.collector.FullLineCompletionInputBuilder$buildRecentContext$1.invokeSuspend(FullLineCompletionInputBuilder.kt)
	at kotlin.coroutines.jvm.internal.BaseContinuationImpl.resumeWith(ContinuationImpl.kt:33)
	at kotlinx.coroutines.UndispatchedCoroutine.afterResume(CoroutineContext.kt:277)
	at kotlinx.coroutines.AbstractCoroutine.resumeWith(AbstractCoroutine.kt:99)
	at kotlin.coroutines.jvm.internal.BaseContinuationImpl.resumeWith(ContinuationImpl.kt:46)
	at kotlinx.coroutines.DispatchedTask.run(DispatchedTask.kt:102)
	at kotlinx.coroutines.scheduling.CoroutineScheduler.runSafely(CoroutineScheduler.kt:608)
	at kotlinx.coroutines.scheduling.CoroutineScheduler$Worker.executeTask(CoroutineScheduler.kt:873)
	at kotlinx.coroutines.scheduling.CoroutineScheduler$Worker.runWorker(CoroutineScheduler.kt:763)
	at kotlinx.coroutines.scheduling.CoroutineScheduler$Worker.run(CoroutineScheduler.kt:750)
Caused by: kotlinx.coroutines.JobCancellationException: LazyStandaloneCoroutine was cancelled; job=LazyStandaloneCoroutine{Cancelling}@24dd1a81
2025-08-31 18:05:34,739 [2401939]   WARN - #o.j.c.f.l.l.s.c.FullLineCompletionInputBuilder - LazyStandaloneCoroutine was cancelled
java.lang.Throwable: Control-flow exceptions (e.g. this class kotlinx.coroutines.JobCancellationException) should never be logged. Instead, these should have been rethrown if caught.
	at com.intellij.openapi.diagnostic.Logger.ensureNotControlFlow(Logger.java:503)
	at com.intellij.idea.IdeaLogger.warn(IdeaLogger.java:124)
	at com.intellij.openapi.diagnostic.Logger.warn(Logger.java:353)
	at org.jetbrains.completion.full.line.local.suggest.collector.FullLineCompletionInputBuilder.buildRecentContext(FullLineCompletionInputBuilder.kt:150)
	at org.jetbrains.completion.full.line.local.suggest.collector.FullLineCompletionInputBuilder.access$buildRecentContext(FullLineCompletionInputBuilder.kt:30)
	at org.jetbrains.completion.full.line.local.suggest.collector.FullLineCompletionInputBuilder$buildRecentContext$1.invokeSuspend(FullLineCompletionInputBuilder.kt)
	at kotlin.coroutines.jvm.internal.BaseContinuationImpl.resumeWith(ContinuationImpl.kt:33)
	at kotlinx.coroutines.UndispatchedCoroutine.afterResume(CoroutineContext.kt:277)
	at kotlinx.coroutines.AbstractCoroutine.resumeWith(AbstractCoroutine.kt:99)
	at kotlin.coroutines.jvm.internal.BaseContinuationImpl.resumeWith(ContinuationImpl.kt:46)
	at kotlinx.coroutines.DispatchedTask.run(DispatchedTask.kt:102)
	at kotlinx.coroutines.scheduling.CoroutineScheduler.runSafely(CoroutineScheduler.kt:608)
	at kotlinx.coroutines.scheduling.CoroutineScheduler$Worker.executeTask(CoroutineScheduler.kt:873)
	at kotlinx.coroutines.scheduling.CoroutineScheduler$Worker.runWorker(CoroutineScheduler.kt:763)
	at kotlinx.coroutines.scheduling.CoroutineScheduler$Worker.run(CoroutineScheduler.kt:750)
Caused by: kotlinx.coroutines.JobCancellationException: LazyStandaloneCoroutine was cancelled; job=LazyStandaloneCoroutine{Cancelling}@1935f07
2025-08-31 18:05:58,413 [2425613]   WARN - #o.j.c.f.l.i.p.d.a.n.NativeServerDiagnostic$Companion - 2025-08-31 16:05:58.413176 [flcc_grpc_inference_service.cpp:121:prefill] call ended, got an exception 'std::future_error: Broken promise' during execution

2025-08-31 18:05:58,539 [2425739]   WARN - #o.j.c.f.l.i.p.d.a.n.NativeServerDiagnostic$Companion - 2025-08-31 16:05:58.539771 [flcc_grpc_inference_service.cpp:121:prefill] call ended, got an exception 'std::future_error: Broken promise' during execution

2025-08-31 18:06:03,746 [2430946]   WARN - #o.j.c.f.l.l.s.c.FullLineCompletionInputBuilder - LazyStandaloneCoroutine was cancelled
java.lang.Throwable: Control-flow exceptions (e.g. this class kotlinx.coroutines.JobCancellationException) should never be logged. Instead, these should have been rethrown if caught.
	at com.intellij.openapi.diagnostic.Logger.ensureNotControlFlow(Logger.java:503)
	at com.intellij.idea.IdeaLogger.warn(IdeaLogger.java:124)
	at com.intellij.openapi.diagnostic.Logger.warn(Logger.java:353)
	at org.jetbrains.completion.full.line.local.suggest.collector.FullLineCompletionInputBuilder.buildRecentContext(FullLineCompletionInputBuilder.kt:150)
	at org.jetbrains.completion.full.line.local.suggest.collector.FullLineCompletionInputBuilder.access$buildRecentContext(FullLineCompletionInputBuilder.kt:30)
	at org.jetbrains.completion.full.line.local.suggest.collector.FullLineCompletionInputBuilder$buildRecentContext$1.invokeSuspend(FullLineCompletionInputBuilder.kt)
	at kotlin.coroutines.jvm.internal.BaseContinuationImpl.resumeWith(ContinuationImpl.kt:33)
	at kotlinx.coroutines.UndispatchedCoroutine.afterResume(CoroutineContext.kt:277)
	at kotlinx.coroutines.AbstractCoroutine.resumeWith(AbstractCoroutine.kt:99)
	at kotlin.coroutines.jvm.internal.BaseContinuationImpl.resumeWith(ContinuationImpl.kt:46)
	at kotlinx.coroutines.DispatchedTask.run(DispatchedTask.kt:102)
	at kotlinx.coroutines.scheduling.CoroutineScheduler.runSafely(CoroutineScheduler.kt:608)
	at kotlinx.coroutines.scheduling.CoroutineScheduler$Worker.executeTask(CoroutineScheduler.kt:873)
	at kotlinx.coroutines.scheduling.CoroutineScheduler$Worker.runWorker(CoroutineScheduler.kt:763)
	at kotlinx.coroutines.scheduling.CoroutineScheduler$Worker.run(CoroutineScheduler.kt:750)
Caused by: kotlinx.coroutines.JobCancellationException: LazyStandaloneCoroutine was cancelled; job=LazyStandaloneCoroutine{Cancelling}@1b26fade
2025-08-31 18:06:04,133 [2431333]   WARN - #o.j.c.f.l.i.p.d.a.n.NativeServerDiagnostic$Companion - 2025-08-31 16:06:04.133603 [flcc_grpc_inference_service.cpp:121:prefill] call ended, got an exception 'std::future_error: Broken promise' during execution

2025-08-31 18:07:37,252 [2524452]   WARN - #o.j.c.f.l.l.s.c.FullLineCompletionInputBuilder - LazyStandaloneCoroutine was cancelled
java.lang.Throwable: Control-flow exceptions (e.g. this class kotlinx.coroutines.JobCancellationException) should never be logged. Instead, these should have been rethrown if caught.
	at com.intellij.openapi.diagnostic.Logger.ensureNotControlFlow(Logger.java:503)
	at com.intellij.idea.IdeaLogger.warn(IdeaLogger.java:124)
	at com.intellij.openapi.diagnostic.Logger.warn(Logger.java:353)
	at org.jetbrains.completion.full.line.local.suggest.collector.FullLineCompletionInputBuilder.buildRecentContext(FullLineCompletionInputBuilder.kt:150)
	at org.jetbrains.completion.full.line.local.suggest.collector.FullLineCompletionInputBuilder.access$buildRecentContext(FullLineCompletionInputBuilder.kt:30)
	at org.jetbrains.completion.full.line.local.suggest.collector.FullLineCompletionInputBuilder$buildRecentContext$1.invokeSuspend(FullLineCompletionInputBuilder.kt)
	at kotlin.coroutines.jvm.internal.BaseContinuationImpl.resumeWith(ContinuationImpl.kt:33)
	at kotlinx.coroutines.UndispatchedCoroutine.afterResume(CoroutineContext.kt:277)
	at kotlinx.coroutines.AbstractCoroutine.resumeWith(AbstractCoroutine.kt:99)
	at kotlin.coroutines.jvm.internal.BaseContinuationImpl.resumeWith(ContinuationImpl.kt:46)
	at kotlinx.coroutines.DispatchedTask.run(DispatchedTask.kt:102)
	at kotlinx.coroutines.scheduling.CoroutineScheduler.runSafely(CoroutineScheduler.kt:608)
	at kotlinx.coroutines.scheduling.CoroutineScheduler$Worker.executeTask(CoroutineScheduler.kt:873)
	at kotlinx.coroutines.scheduling.CoroutineScheduler$Worker.runWorker(CoroutineScheduler.kt:763)
	at kotlinx.coroutines.scheduling.CoroutineScheduler$Worker.run(CoroutineScheduler.kt:750)
Caused by: kotlinx.coroutines.JobCancellationException: LazyStandaloneCoroutine was cancelled; job=LazyStandaloneCoroutine{Cancelling}@4a72dfa
2025-08-31 18:07:38,315 [2525515]   WARN - #o.j.c.f.l.i.p.d.a.n.NativeServerDiagnostic$Companion - 2025-08-31 16:07:38.315562 [flcc_grpc_inference_service.cpp:121:prefill] call ended, got an exception 'std::future_error: Broken promise' during execution

2025-08-31 18:08:07,973 [2555173]   WARN - #o.j.c.f.l.i.p.d.a.n.NativeServerDiagnostic$Companion - 2025-08-31 16:08:07.973821 [flcc_grpc_inference_service.cpp:121:prefill] call ended, got an exception 'std::future_error: Broken promise' during execution

2025-08-31 18:08:08,145 [2555345]   WARN - #o.j.c.f.l.i.p.d.a.n.NativeServerDiagnostic$Companion - 2025-08-31 16:08:08.145681 [flcc_grpc_inference_service.cpp:121:prefill] call ended, got an exception 'std::future_error: Broken promise' during execution

2025-08-31 18:10:47,159 [2714359]   WARN - #o.j.c.f.l.i.p.d.a.n.NativeServerDiagnostic$Companion - 2025-08-31 16:10:47.159823 [flcc_grpc_inference_service.cpp:121:prefill] call ended, got an exception 'std::future_error: Broken promise' during execution

2025-08-31 18:10:47,370 [2714570]   WARN - #o.j.c.f.l.i.p.d.a.n.NativeServerDiagnostic$Companion - 2025-08-31 16:10:47.370578 [flcc_grpc_inference_service.cpp:121:prefill] call ended, got an exception 'std::future_error: Broken promise' during execution

2025-08-31 18:10:47,497 [2714697]   WARN - #o.j.c.f.l.i.p.d.a.n.NativeServerDiagnostic$Companion - 2025-08-31 16:10:47.497733 [flcc_grpc_inference_service.cpp:121:prefill] call ended, got an exception 'std::future_error: Broken promise' during execution

2025-08-31 18:11:14,270 [2741470]   WARN - #c.i.o.a.e.ActionUtil - Can not find action by id CompileDirty
2025-08-31 18:11:51,995 [2779195]   WARN - #o.j.c.f.l.i.p.d.a.n.NativeServerDiagnostic$Companion - 2025-08-31 16:11:51.994964 [flcc_grpc_inference_service.cpp:121:prefill] call ended, got an exception 'std::future_error: Broken promise' during execution

2025-08-31 18:11:52,595 [2779795]   WARN - #o.j.c.f.l.l.s.c.FullLineCompletionInputBuilder - LazyStandaloneCoroutine was cancelled
java.lang.Throwable: Control-flow exceptions (e.g. this class kotlinx.coroutines.JobCancellationException) should never be logged. Instead, these should have been rethrown if caught.
	at com.intellij.openapi.diagnostic.Logger.ensureNotControlFlow(Logger.java:503)
	at com.intellij.idea.IdeaLogger.warn(IdeaLogger.java:124)
	at com.intellij.openapi.diagnostic.Logger.warn(Logger.java:353)
	at org.jetbrains.completion.full.line.local.suggest.collector.FullLineCompletionInputBuilder.buildRecentContext(FullLineCompletionInputBuilder.kt:150)
	at org.jetbrains.completion.full.line.local.suggest.collector.FullLineCompletionInputBuilder.access$buildRecentContext(FullLineCompletionInputBuilder.kt:30)
	at org.jetbrains.completion.full.line.local.suggest.collector.FullLineCompletionInputBuilder$buildRecentContext$1.invokeSuspend(FullLineCompletionInputBuilder.kt)
	at kotlin.coroutines.jvm.internal.BaseContinuationImpl.resumeWith(ContinuationImpl.kt:33)
	at kotlinx.coroutines.UndispatchedCoroutine.afterResume(CoroutineContext.kt:277)
	at kotlinx.coroutines.AbstractCoroutine.resumeWith(AbstractCoroutine.kt:99)
	at kotlin.coroutines.jvm.internal.BaseContinuationImpl.resumeWith(ContinuationImpl.kt:46)
	at kotlinx.coroutines.DispatchedTask.run(DispatchedTask.kt:102)
	at kotlinx.coroutines.scheduling.CoroutineScheduler.runSafely(CoroutineScheduler.kt:608)
	at kotlinx.coroutines.scheduling.CoroutineScheduler$Worker.executeTask(CoroutineScheduler.kt:873)
	at kotlinx.coroutines.scheduling.CoroutineScheduler$Worker.runWorker(CoroutineScheduler.kt:763)
	at kotlinx.coroutines.scheduling.CoroutineScheduler$Worker.run(CoroutineScheduler.kt:750)
Caused by: kotlinx.coroutines.JobCancellationException: LazyStandaloneCoroutine was cancelled; job=LazyStandaloneCoroutine{Cancelling}@c421656
2025-08-31 18:11:52,694 [2779894]   WARN - #o.j.c.f.l.i.p.d.a.n.NativeServerDiagnostic$Companion - 2025-08-31 16:11:52.694012 [flcc_grpc_inference_service.cpp:121:prefill] call ended, got an exception 'std::future_error: Broken promise' during execution

2025-08-31 18:12:01,675 [2788875]   WARN - #o.j.c.f.l.i.p.d.a.n.NativeServerDiagnostic$Companion - 2025-08-31 16:12:01.675709 [flcc_grpc_inference_service.cpp:121:prefill] call ended, got an exception 'std::future_error: Broken promise' during execution

2025-08-31 18:12:02,893 [2790093]   WARN - #o.j.c.f.l.l.s.c.FullLineCompletionInputBuilder - LazyStandaloneCoroutine was cancelled
java.lang.Throwable: Control-flow exceptions (e.g. this class kotlinx.coroutines.JobCancellationException) should never be logged. Instead, these should have been rethrown if caught.
	at com.intellij.openapi.diagnostic.Logger.ensureNotControlFlow(Logger.java:503)
	at com.intellij.idea.IdeaLogger.warn(IdeaLogger.java:124)
	at com.intellij.openapi.diagnostic.Logger.warn(Logger.java:353)
	at org.jetbrains.completion.full.line.local.suggest.collector.FullLineCompletionInputBuilder.buildRecentContext(FullLineCompletionInputBuilder.kt:150)
	at org.jetbrains.completion.full.line.local.suggest.collector.FullLineCompletionInputBuilder.access$buildRecentContext(FullLineCompletionInputBuilder.kt:30)
	at org.jetbrains.completion.full.line.local.suggest.collector.FullLineCompletionInputBuilder$buildRecentContext$1.invokeSuspend(FullLineCompletionInputBuilder.kt)
	at kotlin.coroutines.jvm.internal.BaseContinuationImpl.resumeWith(ContinuationImpl.kt:33)
	at kotlinx.coroutines.UndispatchedCoroutine.afterResume(CoroutineContext.kt:277)
	at kotlinx.coroutines.AbstractCoroutine.resumeWith(AbstractCoroutine.kt:99)
	at kotlin.coroutines.jvm.internal.BaseContinuationImpl.resumeWith(ContinuationImpl.kt:46)
	at kotlinx.coroutines.DispatchedTask.run(DispatchedTask.kt:102)
	at kotlinx.coroutines.scheduling.CoroutineScheduler.runSafely(CoroutineScheduler.kt:608)
	at kotlinx.coroutines.scheduling.CoroutineScheduler$Worker.executeTask(CoroutineScheduler.kt:873)
	at kotlinx.coroutines.scheduling.CoroutineScheduler$Worker.runWorker(CoroutineScheduler.kt:763)
	at kotlinx.coroutines.scheduling.CoroutineScheduler$Worker.run(CoroutineScheduler.kt:750)
Caused by: kotlinx.coroutines.JobCancellationException: LazyStandaloneCoroutine was cancelled; job=LazyStandaloneCoroutine{Cancelling}@1a825e14
2025-08-31 18:12:03,122 [2790322]   WARN - #o.j.c.f.l.i.p.d.a.n.NativeServerDiagnostic$Companion - 2025-08-31 16:12:03.122016 [flcc_grpc_inference_service.cpp:121:prefill] call ended, got an exception 'std::future_error: Broken promise' during execution

2025-08-31 18:12:16,930 [2804130]   WARN - #o.j.c.f.l.i.p.d.a.n.NativeServerDiagnostic$Companion - 2025-08-31 16:12:16.930093 [flcc_grpc_inference_service.cpp:121:prefill] call ended, got an exception 'std::future_error: Broken promise' during execution

2025-08-31 18:12:17,037 [2804237]   WARN - #o.j.c.f.l.i.p.d.a.n.NativeServerDiagnostic$Companion - 2025-08-31 16:12:17.37551 [flcc_grpc_inference_service.cpp:121:prefill] call ended, got an exception 'std::future_error: Broken promise' during execution

2025-08-31 18:12:18,030 [2805230]   WARN - #o.j.c.f.l.i.p.d.a.n.NativeServerDiagnostic$Companion - 2025-08-31 16:12:18.30309 [flcc_grpc_inference_service.cpp:121:prefill] call ended, got an exception 'std::future_error: Broken promise' during execution

2025-08-31 18:13:04,494 [2851694]   WARN - #o.j.c.f.l.l.s.c.FullLineCompletionInputBuilder - LazyStandaloneCoroutine was cancelled
java.lang.Throwable: Control-flow exceptions (e.g. this class kotlinx.coroutines.JobCancellationException) should never be logged. Instead, these should have been rethrown if caught.
	at com.intellij.openapi.diagnostic.Logger.ensureNotControlFlow(Logger.java:503)
	at com.intellij.idea.IdeaLogger.warn(IdeaLogger.java:124)
	at com.intellij.openapi.diagnostic.Logger.warn(Logger.java:353)
	at org.jetbrains.completion.full.line.local.suggest.collector.FullLineCompletionInputBuilder.buildRecentContext(FullLineCompletionInputBuilder.kt:150)
	at org.jetbrains.completion.full.line.local.suggest.collector.FullLineCompletionInputBuilder.access$buildRecentContext(FullLineCompletionInputBuilder.kt:30)
	at org.jetbrains.completion.full.line.local.suggest.collector.FullLineCompletionInputBuilder$buildRecentContext$1.invokeSuspend(FullLineCompletionInputBuilder.kt)
	at kotlin.coroutines.jvm.internal.BaseContinuationImpl.resumeWith(ContinuationImpl.kt:33)
	at kotlinx.coroutines.UndispatchedCoroutine.afterResume(CoroutineContext.kt:277)
	at kotlinx.coroutines.AbstractCoroutine.resumeWith(AbstractCoroutine.kt:99)
	at kotlin.coroutines.jvm.internal.BaseContinuationImpl.resumeWith(ContinuationImpl.kt:46)
	at kotlinx.coroutines.DispatchedTask.run(DispatchedTask.kt:102)
	at kotlinx.coroutines.scheduling.CoroutineScheduler.runSafely(CoroutineScheduler.kt:608)
	at kotlinx.coroutines.scheduling.CoroutineScheduler$Worker.executeTask(CoroutineScheduler.kt:873)
	at kotlinx.coroutines.scheduling.CoroutineScheduler$Worker.runWorker(CoroutineScheduler.kt:763)
	at kotlinx.coroutines.scheduling.CoroutineScheduler$Worker.run(CoroutineScheduler.kt:750)
Caused by: kotlinx.coroutines.JobCancellationException: LazyStandaloneCoroutine was cancelled; job=LazyStandaloneCoroutine{Cancelling}@60b0394c
2025-08-31 18:13:04,566 [2851766]   WARN - #o.j.c.f.l.i.p.d.a.n.NativeServerDiagnostic$Companion - 2025-08-31 16:13:04.566023 [flcc_grpc_inference_service.cpp:121:prefill] call ended, got an exception 'std::future_error: Broken promise' during execution

2025-08-31 18:13:05,093 [2852293]   WARN - #o.j.c.f.l.i.p.d.a.n.NativeServerDiagnostic$Companion - 2025-08-31 16:13:05.93760 [flcc_grpc_inference_service.cpp:121:prefill] call ended, got an exception 'std::future_error: Broken promise' during execution

2025-08-31 18:13:05,651 [2852851]   WARN - #o.j.c.f.l.l.s.c.FullLineCompletionInputBuilder - LazyStandaloneCoroutine was cancelled
java.lang.Throwable: Control-flow exceptions (e.g. this class kotlinx.coroutines.JobCancellationException) should never be logged. Instead, these should have been rethrown if caught.
	at com.intellij.openapi.diagnostic.Logger.ensureNotControlFlow(Logger.java:503)
	at com.intellij.idea.IdeaLogger.warn(IdeaLogger.java:124)
	at com.intellij.openapi.diagnostic.Logger.warn(Logger.java:353)
	at org.jetbrains.completion.full.line.local.suggest.collector.FullLineCompletionInputBuilder.buildRecentContext(FullLineCompletionInputBuilder.kt:150)
	at org.jetbrains.completion.full.line.local.suggest.collector.FullLineCompletionInputBuilder.access$buildRecentContext(FullLineCompletionInputBuilder.kt:30)
	at org.jetbrains.completion.full.line.local.suggest.collector.FullLineCompletionInputBuilder$buildRecentContext$1.invokeSuspend(FullLineCompletionInputBuilder.kt)
	at kotlin.coroutines.jvm.internal.BaseContinuationImpl.resumeWith(ContinuationImpl.kt:33)
	at kotlinx.coroutines.UndispatchedCoroutine.afterResume(CoroutineContext.kt:277)
	at kotlinx.coroutines.AbstractCoroutine.resumeWith(AbstractCoroutine.kt:99)
	at kotlin.coroutines.jvm.internal.BaseContinuationImpl.resumeWith(ContinuationImpl.kt:46)
	at kotlinx.coroutines.DispatchedTask.run(DispatchedTask.kt:102)
	at kotlinx.coroutines.scheduling.CoroutineScheduler.runSafely(CoroutineScheduler.kt:608)
	at kotlinx.coroutines.scheduling.CoroutineScheduler$Worker.executeTask(CoroutineScheduler.kt:873)
	at kotlinx.coroutines.scheduling.CoroutineScheduler$Worker.runWorker(CoroutineScheduler.kt:763)
	at kotlinx.coroutines.scheduling.CoroutineScheduler$Worker.run(CoroutineScheduler.kt:750)
Caused by: kotlinx.coroutines.JobCancellationException: LazyStandaloneCoroutine was cancelled; job=LazyStandaloneCoroutine{Cancelling}@2851fedf
2025-08-31 18:13:05,730 [2852930]   WARN - #o.j.c.f.l.i.p.d.a.n.NativeServerDiagnostic$Companion - 2025-08-31 16:13:05.730023 [flcc_grpc_inference_service.cpp:121:prefill] call ended, got an exception 'std::future_error: Broken promise' during execution

2025-08-31 18:13:44,689 [2891889]   WARN - #o.j.c.f.l.i.p.d.a.n.NativeServerDiagnostic$Companion - 2025-08-31 16:13:44.689878 [flcc_grpc_inference_service.cpp:121:prefill] call ended, got an exception 'std::future_error: Broken promise' during execution

2025-08-31 18:14:04,975 [2912175]   WARN - #o.j.c.f.l.i.p.d.a.n.NativeServerDiagnostic$Companion - 2025-08-31 16:14:04.975135 [flcc_grpc_inference_service.cpp:121:prefill] call ended, got an exception 'std::future_error: Broken promise' during execution

2025-08-31 18:14:30,036 [2937236]   WARN - #o.j.c.f.l.i.p.d.a.n.NativeServerDiagnostic$Companion - 2025-08-31 16:14:30.36261 [flcc_grpc_inference_service.cpp:121:prefill] call ended, got an exception 'std::future_error: Broken promise' during execution

2025-08-31 18:14:30,142 [2937342]   WARN - #o.j.c.f.l.i.p.d.a.n.NativeServerDiagnostic$Companion - 2025-08-31 16:14:30.142550 [flcc_grpc_inference_service.cpp:121:prefill] call ended, got an exception 'std::future_error: Broken promise' during execution

2025-08-31 18:18:02,638 [3149838]   WARN - #o.j.c.f.l.i.p.d.a.n.NativeServerDiagnostic$Companion - 2025-08-31 16:18:02.638048 [flcc_grpc_inference_service.cpp:121:prefill] call ended, got an exception 'std::future_error: Broken promise' during execution

2025-08-31 18:18:02,735 [3149935]   WARN - #o.j.c.f.l.i.p.d.a.n.NativeServerDiagnostic$Companion - 2025-08-31 16:18:02.735883 [flcc_grpc_inference_service.cpp:121:prefill] call ended, got an exception 'std::future_error: Broken promise' during execution

2025-08-31 18:18:15,317 [3162517]   WARN - #c.i.e.p.OSProcessHandler - Process has been already terminated: /home/jostsmrt/.cargo/bin/cargo check --message-format=json --all --all-targets --no-default-features
2025-08-31 18:21:54,519 [3381719]   WARN - #o.j.c.f.l.i.p.d.a.n.NativeServerDiagnostic$Companion - 2025-08-31 16:21:54.519077 [flcc_grpc_inference_service.cpp:121:prefill] call ended, got an exception 'std::future_error: Broken promise' during execution

2025-08-31 18:21:55,350 [3382550]   WARN - #o.j.c.f.l.i.p.d.a.n.NativeServerDiagnostic$Companion - 2025-08-31 16:21:55.350170 [flcc_grpc_inference_service.cpp:121:prefill] call ended, got an exception 'std::future_error: Broken promise' during execution

2025-08-31 18:21:58,088 [3385288]   WARN - #o.j.c.f.l.i.p.d.a.n.NativeServerDiagnostic$Companion - 2025-08-31 16:21:58.88556 [flcc_grpc_inference_service.cpp:121:prefill] call ended, got an exception 'std::future_error: Broken promise' during execution

2025-08-31 18:22:25,509 [3412709]   WARN - #o.j.c.f.l.i.p.d.a.n.NativeServerDiagnostic$Companion - 2025-08-31 16:22:25.509018 [flcc_grpc_inference_service.cpp:121:prefill] call ended, got an exception 'std::future_error: Broken promise' during execution

2025-08-31 18:22:25,743 [3412943]   WARN - #o.j.c.f.l.i.p.d.a.n.NativeServerDiagnostic$Companion - 2025-08-31 16:22:25.743546 [flcc_grpc_inference_service.cpp:121:prefill] call ended, got an exception 'std::future_error: Broken promise' during execution

2025-08-31 18:22:25,845 [3413045]   WARN - #o.j.c.f.l.i.p.d.a.n.NativeServerDiagnostic$Companion - 2025-08-31 16:22:25.845684 [flcc_grpc_inference_service.cpp:121:prefill] call ended, got an exception 'std::future_error: Broken promise' during execution

2025-08-31 18:22:26,008 [3413208]   WARN - #o.j.c.f.l.i.p.d.a.n.NativeServerDiagnostic$Companion - 2025-08-31 16:22:26.8384 [flcc_grpc_inference_service.cpp:121:prefill] call ended, got an exception 'std::future_error: Broken promise' during execution

2025-08-31 18:22:26,365 [3413565]   WARN - #o.j.c.f.l.i.p.d.a.n.NativeServerDiagnostic$Companion - 2025-08-31 16:22:26.364980 [flcc_grpc_inference_service.cpp:121:prefill] call ended, got an exception 'std::future_error: Broken promise' during execution

2025-08-31 18:22:26,490 [3413690]   WARN - #o.j.c.f.l.i.p.d.a.n.NativeServerDiagnostic$Companion - 2025-08-31 16:22:26.490493 [flcc_grpc_inference_service.cpp:121:prefill] call ended, got an exception 'std::future_error: Broken promise' during execution

2025-08-31 18:22:40,870 [3428070]   WARN - #o.j.c.f.l.i.p.d.a.n.NativeServerDiagnostic$Companion - 2025-08-31 16:22:40.870754 [flcc_grpc_inference_service.cpp:121:prefill] call ended, got an exception 'std::future_error: Broken promise' during execution

2025-08-31 18:22:42,098 [3429298]   WARN - #o.j.c.f.l.i.p.d.a.n.NativeServerDiagnostic$Companion - 2025-08-31 16:22:42.98657 [flcc_grpc_inference_service.cpp:121:prefill] call ended, got an exception 'std::future_error: Broken promise' during execution

2025-08-31 18:23:03,638 [3450838]   WARN - #o.j.c.f.l.i.p.d.a.n.NativeServerDiagnostic$Companion - 2025-08-31 16:23:03.638836 [flcc_grpc_inference_service.cpp:121:prefill] call ended, got an exception 'std::future_error: Broken promise' during execution

2025-08-31 18:23:04,899 [3452099]   WARN - #o.j.c.f.l.i.p.d.a.n.NativeServerDiagnostic$Companion - 2025-08-31 16:23:04.899881 [flcc_grpc_inference_service.cpp:121:prefill] call ended, got an exception 'std::future_error: Broken promise' during execution

2025-08-31 18:23:05,738 [3452938]   WARN - #o.j.c.f.l.i.p.d.a.n.NativeServerDiagnostic$Companion - 2025-08-31 16:23:05.738423 [flcc_grpc_inference_service.cpp:121:prefill] call ended, got an exception 'std::future_error: Broken promise' during execution

2025-08-31 18:34:38,494 [4145694]   WARN - #o.j.c.f.l.l.s.c.FullLineCompletionInputBuilder - LazyStandaloneCoroutine was cancelled
java.lang.Throwable: Control-flow exceptions (e.g. this class kotlinx.coroutines.JobCancellationException) should never be logged. Instead, these should have been rethrown if caught.
	at com.intellij.openapi.diagnostic.Logger.ensureNotControlFlow(Logger.java:503)
	at com.intellij.idea.IdeaLogger.warn(IdeaLogger.java:124)
	at com.intellij.openapi.diagnostic.Logger.warn(Logger.java:353)
	at org.jetbrains.completion.full.line.local.suggest.collector.FullLineCompletionInputBuilder.buildRecentContext(FullLineCompletionInputBuilder.kt:150)
	at org.jetbrains.completion.full.line.local.suggest.collector.FullLineCompletionInputBuilder.access$buildRecentContext(FullLineCompletionInputBuilder.kt:30)
	at org.jetbrains.completion.full.line.local.suggest.collector.FullLineCompletionInputBuilder$buildRecentContext$1.invokeSuspend(FullLineCompletionInputBuilder.kt)
	at kotlin.coroutines.jvm.internal.BaseContinuationImpl.resumeWith(ContinuationImpl.kt:33)
	at kotlinx.coroutines.UndispatchedCoroutine.afterResume(CoroutineContext.kt:277)
	at kotlinx.coroutines.AbstractCoroutine.resumeWith(AbstractCoroutine.kt:99)
	at kotlin.coroutines.jvm.internal.BaseContinuationImpl.resumeWith(ContinuationImpl.kt:46)
	at kotlinx.coroutines.DispatchedTask.run(DispatchedTask.kt:102)
	at kotlinx.coroutines.scheduling.CoroutineScheduler.runSafely(CoroutineScheduler.kt:608)
	at kotlinx.coroutines.scheduling.CoroutineScheduler$Worker.executeTask(CoroutineScheduler.kt:873)
	at kotlinx.coroutines.scheduling.CoroutineScheduler$Worker.runWorker(CoroutineScheduler.kt:763)
	at kotlinx.coroutines.scheduling.CoroutineScheduler$Worker.run(CoroutineScheduler.kt:750)
Caused by: kotlinx.coroutines.JobCancellationException: LazyStandaloneCoroutine was cancelled; job=LazyStandaloneCoroutine{Cancelling}@728ab7d
2025-08-31 18:34:38,783 [4145983]   WARN - #o.j.c.f.l.i.p.d.a.n.NativeServerDiagnostic$Companion - 2025-08-31 16:34:38.783564 [flcc_grpc_inference_service.cpp:121:prefill] call ended, got an exception 'std::future_error: Broken promise' during execution

2025-08-31 18:34:38,887 [4146087]   WARN - #o.j.c.f.l.i.p.d.a.n.NativeServerDiagnostic$Companion - 2025-08-31 16:34:38.887672 [flcc_grpc_inference_service.cpp:121:prefill] call ended, got an exception 'std::future_error: Broken promise' during execution

2025-08-31 18:37:39,131 [4326331]   WARN - #o.j.c.f.l.l.s.c.FullLineCompletionInputBuilder - LazyStandaloneCoroutine was cancelled
java.lang.Throwable: Control-flow exceptions (e.g. this class kotlinx.coroutines.JobCancellationException) should never be logged. Instead, these should have been rethrown if caught.
	at com.intellij.openapi.diagnostic.Logger.ensureNotControlFlow(Logger.java:503)
	at com.intellij.idea.IdeaLogger.warn(IdeaLogger.java:124)
	at com.intellij.openapi.diagnostic.Logger.warn(Logger.java:353)
	at org.jetbrains.completion.full.line.local.suggest.collector.FullLineCompletionInputBuilder.buildRecentContext(FullLineCompletionInputBuilder.kt:150)
	at org.jetbrains.completion.full.line.local.suggest.collector.FullLineCompletionInputBuilder.access$buildRecentContext(FullLineCompletionInputBuilder.kt:30)
	at org.jetbrains.completion.full.line.local.suggest.collector.FullLineCompletionInputBuilder$buildRecentContext$1.invokeSuspend(FullLineCompletionInputBuilder.kt)
	at kotlin.coroutines.jvm.internal.BaseContinuationImpl.resumeWith(ContinuationImpl.kt:33)
	at kotlinx.coroutines.UndispatchedCoroutine.afterResume(CoroutineContext.kt:277)
	at kotlinx.coroutines.AbstractCoroutine.resumeWith(AbstractCoroutine.kt:99)
	at kotlin.coroutines.jvm.internal.BaseContinuationImpl.resumeWith(ContinuationImpl.kt:46)
	at kotlinx.coroutines.DispatchedTask.run(DispatchedTask.kt:102)
	at kotlinx.coroutines.scheduling.CoroutineScheduler.runSafely(CoroutineScheduler.kt:608)
	at kotlinx.coroutines.scheduling.CoroutineScheduler$Worker.executeTask(CoroutineScheduler.kt:873)
	at kotlinx.coroutines.scheduling.CoroutineScheduler$Worker.runWorker(CoroutineScheduler.kt:763)
	at kotlinx.coroutines.scheduling.CoroutineScheduler$Worker.run(CoroutineScheduler.kt:750)
Caused by: kotlinx.coroutines.JobCancellationException: LazyStandaloneCoroutine was cancelled; job=LazyStandaloneCoroutine{Cancelling}@17297678
2025-08-31 18:37:40,507 [4327707]   WARN - #o.j.c.f.l.i.p.d.a.n.NativeServerDiagnostic$Companion - 2025-08-31 16:37:40.507079 [flcc_grpc_inference_service.cpp:121:prefill] call ended, got an exception 'std::future_error: Broken promise' during execution

2025-08-31 18:37:40,820 [4328020]   WARN - #o.j.c.f.l.i.p.d.a.n.NativeServerDiagnostic$Companion - 2025-08-31 16:37:40.819947 [flcc_grpc_inference_service.cpp:121:prefill] call ended, got an exception 'std::future_error: Broken promise' during execution

2025-08-31 18:37:41,879 [4329079]   WARN - #o.j.c.f.l.i.p.d.a.n.NativeServerDiagnostic$Companion - 2025-08-31 16:37:41.878881 [flcc_grpc_inference_service.cpp:121:prefill] call ended, got an exception 'std::future_error: Broken promise' during execution

2025-08-31 18:37:42,067 [4329267]   WARN - #o.j.c.f.l.i.p.d.a.n.NativeServerDiagnostic$Companion - 2025-08-31 16:37:42.67602 [flcc_grpc_inference_service.cpp:121:prefill] call ended, got an exception 'std::future_error: Broken promise' during execution

2025-08-31 18:37:42,193 [4329393]   WARN - #o.j.c.f.l.i.p.d.a.n.NativeServerDiagnostic$Companion - 2025-08-31 16:37:42.193274 [flcc_grpc_inference_service.cpp:121:prefill] call ended, got an exception 'std::future_error: Broken promise' during execution

2025-08-31 18:37:42,364 [4329564]   WARN - #o.j.c.f.l.i.p.d.a.n.NativeServerDiagnostic$Companion - 2025-08-31 16:37:42.364085 [flcc_grpc_inference_service.cpp:121:prefill] call ended, got an exception 'std::future_error: Broken promise' during execution

2025-08-31 18:37:42,608 [4329808]   WARN - #o.j.c.f.l.i.p.d.a.n.NativeServerDiagnostic$Companion - 2025-08-31 16:37:42.608353 [flcc_grpc_inference_service.cpp:121:prefill] call ended, got an exception 'std::future_error: Broken promise' during execution

2025-08-31 18:37:43,019 [4330219]   WARN - #o.j.c.f.l.i.p.d.a.n.NativeServerDiagnostic$Companion - 2025-08-31 16:37:43.19519 [flcc_grpc_inference_service.cpp:121:prefill] call ended, got an exception 'std::future_error: Broken promise' during execution

2025-08-31 18:38:20,195 [4367395]   WARN - #c.i.e.p.OSProcessHandler - Process has been already terminated: /home/jostsmrt/.cargo/bin/cargo check --bin shnek --message-format=json --no-default-features --tests
2025-08-31 18:44:01,222 [4708422]   WARN - #c.i.i.a.CopyTBXReferenceAction - Cannot find TBX tool for IDE: RustRover
2025-08-31 18:44:16,685 [4723885]   WARN - #c.i.i.a.CopyTBXReferenceAction - Cannot find TBX tool for IDE: RustRover
2025-08-31 18:44:45,688 [4752888]   WARN - #o.j.c.f.l.i.p.d.a.n.NativeServerDiagnostic$Companion - 2025-08-31 16:44:45.688597 [flcc_grpc_inference_service.cpp:121:prefill] call ended, got an exception 'std::future_error: Broken promise' during execution

2025-08-31 18:44:46,007 [4753207]   WARN - #o.j.c.f.l.i.p.d.a.n.NativeServerDiagnostic$Companion - 2025-08-31 16:44:46.6981 [flcc_grpc_inference_service.cpp:121:prefill] call ended, got an exception 'std::future_error: Broken promise' during execution

2025-08-31 18:45:03,237 [4770437]   WARN - #o.j.c.f.l.i.p.d.a.n.NativeServerDiagnostic$Companion - 2025-08-31 16:45:03.237275 [flcc_grpc_inference_service.cpp:121:prefill] call ended, got an exception 'std::future_error: Broken promise' during execution

2025-08-31 18:45:03,598 [4770798]   WARN - #o.j.c.f.l.i.p.d.a.n.NativeServerDiagnostic$Companion - 2025-08-31 16:45:03.598382 [flcc_grpc_inference_service.cpp:121:prefill] call ended, got an exception 'std::future_error: Broken promise' during execution

2025-08-31 18:45:03,730 [4770930]   WARN - #o.j.c.f.l.i.p.d.a.n.NativeServerDiagnostic$Companion - 2025-08-31 16:45:03.730292 [flcc_grpc_inference_service.cpp:121:prefill] call ended, got an exception 'std::future_error: Broken promise' during execution

2025-08-31 18:46:56,247 [4883447]   WARN - #o.j.c.f.l.i.p.d.a.n.NativeServerDiagnostic$Companion - 2025-08-31 16:46:56.247098 [flcc_grpc_inference_service.cpp:121:prefill] call ended, got an exception 'std::future_error: Broken promise' during execution

2025-08-31 18:50:33,074 [5100274]   WARN - #o.j.c.f.l.l.s.c.FullLineCompletionInputBuilder - LazyStandaloneCoroutine was cancelled
java.lang.Throwable: Control-flow exceptions (e.g. this class kotlinx.coroutines.JobCancellationException) should never be logged. Instead, these should have been rethrown if caught.
	at com.intellij.openapi.diagnostic.Logger.ensureNotControlFlow(Logger.java:503)
	at com.intellij.idea.IdeaLogger.warn(IdeaLogger.java:124)
	at com.intellij.openapi.diagnostic.Logger.warn(Logger.java:353)
	at org.jetbrains.completion.full.line.local.suggest.collector.FullLineCompletionInputBuilder.buildRecentContext(FullLineCompletionInputBuilder.kt:150)
	at org.jetbrains.completion.full.line.local.suggest.collector.FullLineCompletionInputBuilder.access$buildRecentContext(FullLineCompletionInputBuilder.kt:30)
	at org.jetbrains.completion.full.line.local.suggest.collector.FullLineCompletionInputBuilder$buildRecentContext$1.invokeSuspend(FullLineCompletionInputBuilder.kt)
	at kotlin.coroutines.jvm.internal.BaseContinuationImpl.resumeWith(ContinuationImpl.kt:33)
	at kotlinx.coroutines.UndispatchedCoroutine.afterResume(CoroutineContext.kt:277)
	at kotlinx.coroutines.AbstractCoroutine.resumeWith(AbstractCoroutine.kt:99)
	at kotlin.coroutines.jvm.internal.BaseContinuationImpl.resumeWith(ContinuationImpl.kt:46)
	at kotlinx.coroutines.DispatchedTask.run(DispatchedTask.kt:102)
	at kotlinx.coroutines.scheduling.CoroutineScheduler.runSafely(CoroutineScheduler.kt:608)
	at kotlinx.coroutines.scheduling.CoroutineScheduler$Worker.executeTask(CoroutineScheduler.kt:873)
	at kotlinx.coroutines.scheduling.CoroutineScheduler$Worker.runWorker(CoroutineScheduler.kt:763)
	at kotlinx.coroutines.scheduling.CoroutineScheduler$Worker.run(CoroutineScheduler.kt:750)
Caused by: kotlinx.coroutines.JobCancellationException: LazyStandaloneCoroutine was cancelled; job=LazyStandaloneCoroutine{Cancelling}@3db81a36
2025-08-31 18:50:57,332 [5124532]   WARN - #o.j.c.f.l.i.p.d.a.n.NativeServerDiagnostic$Companion - 2025-08-31 16:50:57.332862 [flcc_grpc_inference_service.cpp:121:prefill] call ended, got an exception 'std::future_error: Broken promise' during execution

2025-08-31 18:50:57,412 [5124612]   WARN - #o.j.c.f.l.i.p.d.a.n.NativeServerDiagnostic$Companion - 2025-08-31 16:50:57.412209 [flcc_grpc_inference_service.cpp:121:prefill] call ended, got an exception 'std::future_error: Broken promise' during execution

2025-08-31 18:50:57,574 [5124774]   WARN - #o.j.c.f.l.i.p.d.a.n.NativeServerDiagnostic$Companion - 2025-08-31 16:50:57.574448 [flcc_grpc_inference_service.cpp:121:prefill] call ended, got an exception 'std::future_error: Broken promise' during execution

2025-08-31 18:51:00,096 [5127296]   WARN - #o.j.c.f.l.l.s.c.FullLineCompletionInputBuilder - LazyStandaloneCoroutine was cancelled
java.lang.Throwable: Control-flow exceptions (e.g. this class kotlinx.coroutines.JobCancellationException) should never be logged. Instead, these should have been rethrown if caught.
	at com.intellij.openapi.diagnostic.Logger.ensureNotControlFlow(Logger.java:503)
	at com.intellij.idea.IdeaLogger.warn(IdeaLogger.java:124)
	at com.intellij.openapi.diagnostic.Logger.warn(Logger.java:353)
	at org.jetbrains.completion.full.line.local.suggest.collector.FullLineCompletionInputBuilder.buildRecentContext(FullLineCompletionInputBuilder.kt:150)
	at org.jetbrains.completion.full.line.local.suggest.collector.FullLineCompletionInputBuilder.access$buildRecentContext(FullLineCompletionInputBuilder.kt:30)
	at org.jetbrains.completion.full.line.local.suggest.collector.FullLineCompletionInputBuilder$buildRecentContext$1.invokeSuspend(FullLineCompletionInputBuilder.kt)
	at kotlin.coroutines.jvm.internal.BaseContinuationImpl.resumeWith(ContinuationImpl.kt:33)
	at kotlinx.coroutines.UndispatchedCoroutine.afterResume(CoroutineContext.kt:277)
	at kotlinx.coroutines.AbstractCoroutine.resumeWith(AbstractCoroutine.kt:99)
	at kotlin.coroutines.jvm.internal.BaseContinuationImpl.resumeWith(ContinuationImpl.kt:46)
	at kotlinx.coroutines.DispatchedTask.run(DispatchedTask.kt:102)
	at kotlinx.coroutines.scheduling.CoroutineScheduler.runSafely(CoroutineScheduler.kt:608)
	at kotlinx.coroutines.scheduling.CoroutineScheduler$Worker.executeTask(CoroutineScheduler.kt:873)
	at kotlinx.coroutines.scheduling.CoroutineScheduler$Worker.runWorker(CoroutineScheduler.kt:763)
	at kotlinx.coroutines.scheduling.CoroutineScheduler$Worker.run(CoroutineScheduler.kt:750)
Caused by: kotlinx.coroutines.JobCancellationException: LazyStandaloneCoroutine was cancelled; job=LazyStandaloneCoroutine{Cancelling}@186ddcd6
2025-08-31 18:51:00,890 [5128090]   WARN - #o.j.c.f.l.l.s.c.FullLineCompletionInputBuilder - LazyStandaloneCoroutine was cancelled
java.lang.Throwable: Control-flow exceptions (e.g. this class kotlinx.coroutines.JobCancellationException) should never be logged. Instead, these should have been rethrown if caught.
	at com.intellij.openapi.diagnostic.Logger.ensureNotControlFlow(Logger.java:503)
	at com.intellij.idea.IdeaLogger.warn(IdeaLogger.java:124)
	at com.intellij.openapi.diagnostic.Logger.warn(Logger.java:353)
	at org.jetbrains.completion.full.line.local.suggest.collector.FullLineCompletionInputBuilder.buildRecentContext(FullLineCompletionInputBuilder.kt:150)
	at org.jetbrains.completion.full.line.local.suggest.collector.FullLineCompletionInputBuilder.access$buildRecentContext(FullLineCompletionInputBuilder.kt:30)
	at org.jetbrains.completion.full.line.local.suggest.collector.FullLineCompletionInputBuilder$buildRecentContext$1.invokeSuspend(FullLineCompletionInputBuilder.kt)
	at kotlin.coroutines.jvm.internal.BaseContinuationImpl.resumeWith(ContinuationImpl.kt:33)
	at kotlinx.coroutines.UndispatchedCoroutine.afterResume(CoroutineContext.kt:277)
	at kotlinx.coroutines.AbstractCoroutine.resumeWith(AbstractCoroutine.kt:99)
	at kotlin.coroutines.jvm.internal.BaseContinuationImpl.resumeWith(ContinuationImpl.kt:46)
	at kotlinx.coroutines.DispatchedTask.run(DispatchedTask.kt:102)
	at kotlinx.coroutines.scheduling.CoroutineScheduler.runSafely(CoroutineScheduler.kt:608)
	at kotlinx.coroutines.scheduling.CoroutineScheduler$Worker.executeTask(CoroutineScheduler.kt:873)
	at kotlinx.coroutines.scheduling.CoroutineScheduler$Worker.runWorker(CoroutineScheduler.kt:763)
	at kotlinx.coroutines.scheduling.CoroutineScheduler$Worker.run(CoroutineScheduler.kt:750)
Caused by: kotlinx.coroutines.JobCancellationException: LazyStandaloneCoroutine was cancelled; job=LazyStandaloneCoroutine{Cancelling}@5cda374
2025-08-31 18:51:00,962 [5128162]   WARN - #o.j.c.f.l.i.p.d.a.n.NativeServerDiagnostic$Companion - 2025-08-31 16:51:00.962856 [flcc_grpc_inference_service.cpp:121:prefill] call ended, got an exception 'std::future_error: Broken promise' during execution

2025-08-31 18:51:01,046 [5128246]   WARN - #o.j.c.f.l.i.p.d.a.n.NativeServerDiagnostic$Companion - 2025-08-31 16:51:01.46446 [flcc_grpc_inference_service.cpp:121:prefill] call ended, got an exception 'std::future_error: Broken promise' during execution

2025-08-31 18:51:01,790 [5128990]   WARN - #o.j.c.f.l.i.p.d.a.n.NativeServerDiagnostic$Companion - 2025-08-31 16:51:01.790135 [flcc_grpc_inference_service.cpp:121:prefill] call ended, got an exception 'std::future_error: Broken promise' during execution

2025-08-31 18:51:02,886 [5130086]   WARN - #o.j.c.f.l.i.p.d.a.n.NativeServerDiagnostic$Companion - 2025-08-31 16:51:02.886263 [flcc_grpc_inference_service.cpp:121:prefill] call ended, got an exception 'std::future_error: Broken promise' during execution

2025-08-31 18:51:03,139 [5130339]   WARN - #o.j.c.f.l.i.p.d.a.n.NativeServerDiagnostic$Companion - 2025-08-31 16:51:03.139164 [flcc_grpc_inference_service.cpp:121:prefill] call ended, got an exception 'std::future_error: Broken promise' during execution

2025-08-31 18:51:03,377 [5130577]   WARN - #o.j.c.f.l.i.p.d.a.n.NativeServerDiagnostic$Companion - 2025-08-31
2025-08-31 18:51:03,377 [5130577]   WARN - #o.j.c.f.l.i.p.d.a.n.NativeServerDiagnostic$Companion -  16:51:03.377346 [flcc_grpc_inference_service.cpp:121:prefill] call ended, got an exception 'std::future_error: Broken promise' during execution

2025-08-31 18:53:42,045 [5289245]   WARN - #c.i.e.p.OSProcessHandler - Process has been already terminated: /home/jostsmrt/.cargo/bin/cargo check --message-format=json --all --all-targets --no-default-features
2025-08-31 18:54:16,651 [5323851]   WARN - #o.j.c.f.l.i.p.d.a.n.NativeServerDiagnostic$Companion - 2025-08-31 16:54:16.651494 [flcc_grpc_inference_service.cpp:121:prefill] call ended, got an exception 'std::future_error: Broken promise' during execution

2025-08-31 18:54:16,805 [5324005]   WARN - #o.j.c.f.l.i.p.d.a.n.NativeServerDiagnostic$Companion - 2025-08-31 16:54:16.805465 [flcc_grpc_inference_service.cpp:121:prefill] call ended, got an exception 'std::future_error: Broken promise' during execution

2025-08-31 18:54:16,902 [5324102]   WARN - #o.j.c.f.l.i.p.d.a.n.NativeServerDiagnostic$Companion - 2025-08-31 16:54:16.902037 [flcc_grpc_inference_service.cpp:121:prefill] call ended, got an exception 'std::future_error: Broken promise' during execution

2025-08-31 18:54:17,065 [5324265]   WARN - #o.j.c.f.l.i.p.d.a.n.NativeServerDiagnostic$Companion - 2025-08-31 16:54:17.65692 [flcc_grpc_inference_service.cpp:121:prefill] call ended, got an exception 'std::future_error: Broken promise' during execution

2025-08-31 18:54:18,349 [5325549]   WARN - #o.j.c.f.l.i.p.d.a.n.NativeServerDiagnostic$Companion - 2025-08-31 16:54:18.349595 [flcc_grpc_inference_service.cpp:121:prefill] call ended, got an exception 'std::future_error: Broken promise' during execution

2025-08-31 18:54:19,350 [5326550]   WARN - #o.j.c.f.l.i.p.d.a.n.NativeServerDiagnostic$Companion - 2025-08-31 16:54:19.350650 [flcc_grpc_inference_service.cpp:121:prefill] call ended, got an exception 'std::future_error: Broken promise' during execution

2025-08-31 18:55:05,936 [5373136]   WARN - #o.j.c.f.l.i.p.d.a.n.NativeServerDiagnostic$Companion - 2025-08-31 16:55:05.936626 [flcc_grpc_inference_service.cpp:121:prefill] call ended, got an exception 'std::future_error: Broken promise' during execution

2025-08-31 18:55:06,110 [5373310]   WARN - #o.j.c.f.l.i.p.d.a.n.NativeServerDiagnostic$Companion - 2025-08-31 16:55:06.110087 [flcc_grpc_inference_service.cpp:121:prefill] call ended, got an exception 'std::future_error: Broken promise' during execution

2025-08-31 18:55:06,246 [5373446]   WARN - #o.j.c.f.l.i.p.d.a.n.NativeServerDiagnostic$Companion - 2025-08-31 16:55:06.246457 [flcc_grpc_inference_service.cpp:121:prefill] call ended, got an exception 'std::future_error: Broken promise' during execution

2025-08-31 18:55:06,388 [5373588]   WARN - #o.j.c.f.l.i.p.d.a.n.NativeServerDiagnostic$Companion - 2025-08-31 16:55:06.388242 [flcc_grpc_inference_service.cpp:121:prefill] call ended, got an exception 'std::future_error: Broken promise' during execution

2025-08-31 18:55:06,601 [5373801]   WARN - #o.j.c.f.l.i.p.d.a.n.NativeServerDiagnostic$Companion - 2025-08-31 16:55:06.601438 [flcc_grpc_inference_service.cpp:121:prefill] call ended, got an exception 'std::future_error: Broken promise' during execution

2025-08-31 18:55:06,695 [5373895]   WARN - #o.j.c.f.l.i.p.d.a.n.NativeServerDiagnostic$Companion - 2025-08-31 16:55:06.695801 [flcc_grpc_inference_service.cpp:121:prefill] call ended, got an exception 'std::future_error: Broken promise' during execution

2025-08-31 18:55:06,819 [5374019]   WARN - #o.j.c.f.l.i.p.d.a.n.NativeServerDiagnostic$Companion - 2025-08-31 16:55:06.819318 [flcc_grpc_inference_service.cpp:121:prefill] call ended, got an exception 'std::future_error: Broken promise' during execution

2025-08-31 18:58:37,411 [5584611]   WARN - #o.j.c.f.l.i.p.d.a.n.NativeServerDiagnostic$Companion - 2025-08-31 16:58:37.411697 [flcc_grpc_inference_service.cpp:121:prefill] call ended, got an exception 'std::future_error: Broken promise' during execution

2025-08-31 18:58:37,521 [5584721]   WARN - #o.j.c.f.l.i.p.d.a.n.NativeServerDiagnostic$Companion - 2025-08-31 16:58:37.520964 [flcc_grpc_inference_service.cpp:121:prefill] call ended, got an exception 'std::future_error: Broken promise' during execution

2025-08-31 18:58:37,690 [5584890]   WARN - #o.j.c.f.l.i.p.d.a.n.NativeServerDiagnostic$Companion - 2025-08-31 16:58:37.689839 [flcc_grpc_inference_service.cpp:121:prefill] call ended, got an exception 'std::future_error: Broken promise' during execution

2025-08-31 18:58:38,608 [5585808]   WARN - #c.i.e.p.OSProcessHandler - Process has been already terminated: /home/jostsmrt/.cargo/bin/cargo check --message-format=json --all --all-targets --no-default-features
2025-08-31 18:58:38,656 [5585856]   WARN - #o.j.c.f.l.i.p.d.a.n.NativeServerDiagnostic$Companion - 2025-08-31 16:58:38.656875 [flcc_grpc_inference_service.cpp:121:prefill] call ended, got an exception 'std::future_error: Broken promise' during execution

2025-08-31 18:59:22,722 [5629922]   WARN - #o.j.c.f.l.l.s.c.FullLineCompletionInputBuilder - LazyStandaloneCoroutine was cancelled
java.lang.Throwable: Control-flow exceptions (e.g. this class kotlinx.coroutines.JobCancellationException) should never be logged. Instead, these should have been rethrown if caught.
	at com.intellij.openapi.diagnostic.Logger.ensureNotControlFlow(Logger.java:503)
	at com.intellij.idea.IdeaLogger.warn(IdeaLogger.java:124)
	at com.intellij.openapi.diagnostic.Logger.warn(Logger.java:353)
	at org.jetbrains.completion.full.line.local.suggest.collector.FullLineCompletionInputBuilder.buildRecentContext(FullLineCompletionInputBuilder.kt:150)
	at org.jetbrains.completion.full.line.local.suggest.collector.FullLineCompletionInputBuilder.access$buildRecentContext(FullLineCompletionInputBuilder.kt:30)
	at org.jetbrains.completion.full.line.local.suggest.collector.FullLineCompletionInputBuilder$buildRecentContext$1.invokeSuspend(FullLineCompletionInputBuilder.kt)
	at kotlin.coroutines.jvm.internal.BaseContinuationImpl.resumeWith(ContinuationImpl.kt:33)
	at kotlinx.coroutines.UndispatchedCoroutine.afterResume(CoroutineContext.kt:277)
	at kotlinx.coroutines.AbstractCoroutine.resumeWith(AbstractCoroutine.kt:99)
	at kotlin.coroutines.jvm.internal.BaseContinuationImpl.resumeWith(ContinuationImpl.kt:46)
	at kotlinx.coroutines.DispatchedTask.run(DispatchedTask.kt:102)
	at kotlinx.coroutines.scheduling.CoroutineScheduler.runSafely(CoroutineScheduler.kt:608)
	at kotlinx.coroutines.scheduling.CoroutineScheduler$Worker.executeTask(CoroutineScheduler.kt:873)
	at kotlinx.coroutines.scheduling.CoroutineScheduler$Worker.runWorker(CoroutineScheduler.kt:763)
	at kotlinx.coroutines.scheduling.CoroutineScheduler$Worker.run(CoroutineScheduler.kt:750)
Caused by: kotlinx.coroutines.JobCancellationException: LazyStandaloneCoroutine was cancelled; job=LazyStandaloneCoroutine{Cancelling}@32eb201c
2025-08-31 18:59:23,014 [5630214]   WARN - #o.j.c.f.l.i.p.d.a.n.NativeServerDiagnostic$Companion - 2025-08-31 16:59:23.14251 [flcc_grpc_inference_service.cpp:121:prefill] call ended, got an exception 'std::future_error: Broken promise' during execution

2025-08-31 18:59:23,191 [5630391]   WARN - #o.j.c.f.l.i.p.d.a.n.NativeServerDiagnostic$Companion - 2025-08-31 16:59:23.191791 [flcc_grpc_inference_service.cpp:121:prefill] call ended, got an exception 'std::future_error: Broken promise' during execution

2025-08-31 18:59:23,305 [5630505]   WARN - #o.j.c.f.l.i.p.d.a.n.NativeServerDiagnostic$Companion - 2025-08-31 16:59:23.305683 [flcc_grpc_inference_service.cpp:121:prefill] call ended, got an exception 'std::future_error: Broken promise' during execution

2025-08-31 18:59:23,433 [5630633]   WARN - #o.j.c.f.l.i.p.d.a.n.NativeServerDiagnostic$Companion - 2025-08-31 16:59:23.433513 [flcc_grpc_inference_service.cpp:121:prefill] call ended, got an exception 'std::future_error: Broken promise' during execution

2025-08-31 18:59:47,793 [5654993]   WARN - #o.j.c.f.l.l.s.c.FullLineCompletionInputBuilder - LazyStandaloneCoroutine was cancelled
java.lang.Throwable: Control-flow exceptions (e.g. this class kotlinx.coroutines.JobCancellationException) should never be logged. Instead, these should have been rethrown if caught.
	at com.intellij.openapi.diagnostic.Logger.ensureNotControlFlow(Logger.java:503)
	at com.intellij.idea.IdeaLogger.warn(IdeaLogger.java:124)
	at com.intellij.openapi.diagnostic.Logger.warn(Logger.java:353)
	at org.jetbrains.completion.full.line.local.suggest.collector.FullLineCompletionInputBuilder.buildRecentContext(FullLineCompletionInputBuilder.kt:150)
	at org.jetbrains.completion.full.line.local.suggest.collector.FullLineCompletionInputBuilder.access$buildRecentContext(FullLineCompletionInputBuilder.kt:30)
	at org.jetbrains.completion.full.line.local.suggest.collector.FullLineCompletionInputBuilder$buildRecentContext$1.invokeSuspend(FullLineCompletionInputBuilder.kt)
	at kotlin.coroutines.jvm.internal.BaseContinuationImpl.resumeWith(ContinuationImpl.kt:33)
	at kotlinx.coroutines.UndispatchedCoroutine.afterResume(CoroutineContext.kt:277)
	at kotlinx.coroutines.AbstractCoroutine.resumeWith(AbstractCoroutine.kt:99)
	at kotlin.coroutines.jvm.internal.BaseContinuationImpl.resumeWith(ContinuationImpl.kt:46)
	at kotlinx.coroutines.DispatchedTask.run(DispatchedTask.kt:102)
	at kotlinx.coroutines.scheduling.CoroutineScheduler.runSafely(CoroutineScheduler.kt:608)
	at kotlinx.coroutines.scheduling.CoroutineScheduler$Worker.executeTask(CoroutineScheduler.kt:873)
	at kotlinx.coroutines.scheduling.CoroutineScheduler$Worker.runWorker(CoroutineScheduler.kt:763)
	at kotlinx.coroutines.scheduling.CoroutineScheduler$Worker.run(CoroutineScheduler.kt:750)
Caused by: kotlinx.coroutines.JobCancellationException: LazyStandaloneCoroutine was cancelled; job=LazyStandaloneCoroutine{Cancelling}@7bb4f87
2025-08-31 18:59:48,257 [5655457]   WARN - #o.j.c.f.l.i.p.d.a.n.NativeServerDiagnostic$Companion - 2025-08-31 16:59:48.257279 [flcc_grpc_inference_service.cpp:121:prefill] call ended, got an exception 'std::future_error: Broken promise' during execution

2025-08-31 18:59:48,882 [5656082]   WARN - #o.j.c.f.l.i.p.d.a.n.NativeServerDiagnostic$Companion - 2025-08-31 16:59:48.881831 [flcc_grpc_inference_service.cpp:121:prefill] call ended, got an exception 'std::future_error: Broken promise' during execution

2025-08-31 19:03:12,980 [5860180]   WARN - #o.j.c.f.l.l.s.c.FullLineCompletionInputBuilder - LazyStandaloneCoroutine was cancelled
java.lang.Throwable: Control-flow exceptions (e.g. this class kotlinx.coroutines.JobCancellationException) should never be logged. Instead, these should have been rethrown if caught.
	at com.intellij.openapi.diagnostic.Logger.ensureNotControlFlow(Logger.java:503)
	at com.intellij.idea.IdeaLogger.warn(IdeaLogger.java:124)
	at com.intellij.openapi.diagnostic.Logger.warn(Logger.java:353)
	at org.jetbrains.completion.full.line.local.suggest.collector.FullLineCompletionInputBuilder.buildRecentContext(FullLineCompletionInputBuilder.kt:150)
	at org.jetbrains.completion.full.line.local.suggest.collector.FullLineCompletionInputBuilder.access$buildRecentContext(FullLineCompletionInputBuilder.kt:30)
	at org.jetbrains.completion.full.line.local.suggest.collector.FullLineCompletionInputBuilder$buildRecentContext$1.invokeSuspend(FullLineCompletionInputBuilder.kt)
	at kotlin.coroutines.jvm.internal.BaseContinuationImpl.resumeWith(ContinuationImpl.kt:33)
	at kotlinx.coroutines.UndispatchedCoroutine.afterResume(CoroutineContext.kt:277)
	at kotlinx.coroutines.AbstractCoroutine.resumeWith(AbstractCoroutine.kt:99)
	at kotlin.coroutines.jvm.internal.BaseContinuationImpl.resumeWith(ContinuationImpl.kt:46)
	at kotlinx.coroutines.DispatchedTask.run(DispatchedTask.kt:102)
	at kotlinx.coroutines.scheduling.CoroutineScheduler.runSafely(CoroutineScheduler.kt:608)
	at kotlinx.coroutines.scheduling.CoroutineScheduler$Worker.executeTask(CoroutineScheduler.kt:873)
	at kotlinx.coroutines.scheduling.CoroutineScheduler$Worker.runWorker(CoroutineScheduler.kt:763)
	at kotlinx.coroutines.scheduling.CoroutineScheduler$Worker.run(CoroutineScheduler.kt:750)
Caused by: kotlinx.coroutines.JobCancellationException: LazyStandaloneCoroutine was cancelled; job=LazyStandaloneCoroutine{Cancelling}@2a37f232
2025-08-31 19:03:13,386 [5860586]   WARN - #o.j.c.f.l.i.p.d.a.n.NativeServerDiagnostic$Companion - 2025-08-31 17:03:13.386475 [flcc_grpc_inference_service.cpp:121:prefill] call ended, got an exception 'std::future_error: Broken promise' during execution

2025-08-31 19:03:13,499 [5860699]   WARN - #o.j.c.f.l.i.p.d.a.n.NativeServerDiagnostic$Companion - 2025-08-31 17:03:13.499380 [flcc_grpc_inference_service.cpp:121:prefill] call ended, got an exception 'std::future_error: Broken promise' during execution

2025-08-31 19:03:13,597 [5860797]   WARN - #o.j.c.f.l.i.p.d.a.n.NativeServerDiagnostic$Companion - 2025-08-31 17:03:13.597618 [flcc_grpc_inference_service.cpp:121:prefill] call ended, got an exception 'std::future_error: Broken promise' during execution

2025-08-31 19:03:14,155 [5861355]   WARN - #o.j.c.f.l.i.p.d.a.n.NativeServerDiagnostic$Companion - 2025-08-31 17:03:14.155807 [flcc_grpc_inference_service.cpp:121:prefill] call ended, got an exception 'std::future_error: Broken promise' during execution

2025-08-31 19:03:14,974 [5862174]   WARN - #o.j.c.f.l.i.p.d.a.n.NativeServerDiagnostic$Companion - 2025-08-31 17:03:14.974810 [flcc_grpc_inference_service.cpp:121:prefill] call ended, got an exception 'std::future_error: Broken promise' during execution

2025-08-31 19:03:15,427 [5862627]   WARN - #o.j.c.f.l.i.p.d.a.n.NativeServerDiagnostic$Companion - 2025-08-31 17:03:15.427428 [flcc_grpc_inference_service.cpp:121:prefill] call ended, got an exception 'std::future_error: Broken promise' during execution

2025-08-31 19:03:25,120 [5872320]   WARN - #o.j.c.f.l.i.p.d.a.n.NativeServerDiagnostic$Companion - 2025-08-31 17:03:25.120781 [flcc_grpc_inference_service.cpp:121:prefill] call ended, got an exception 'std::future_error: Broken promise' during execution

2025-08-31 19:03:25,356 [5872556]   WARN - #o.j.c.f.l.i.p.d.a.n.NativeServerDiagnostic$Companion - 2025-08-31 17:03:25.356114 [flcc_grpc_inference_service.cpp:121:prefill] call ended, got an exception 'std::future_error: Broken promise' during execution

2025-08-31 19:03:25,522 [5872722]   WARN - #o.j.c.f.l.i.p.d.a.n.NativeServerDiagnostic$Companion - 2025-08-31 17:03:25.522907 [flcc_grpc_inference_service.cpp:121:prefill] call ended, got an exception 'std::future_error: Broken promise' during execution

2025-08-31 19:03:25,634 [5872834]   WARN - #o.j.c.f.l.i.p.d.a.n.NativeServerDiagnostic$Companion - 2025-08-31 17:03:25.634748 [flcc_grpc_inference_service.cpp:121:prefill] call ended, got an exception 'std::future_error: Broken promise' during execution

2025-08-31 19:03:26,532 [5873732]   WARN - #o.j.c.f.l.i.p.d.a.n.NativeServerDiagnostic$Companion - 2025-08-31 17:03:26.531868 [flcc_grpc_inference_service.cpp:121:prefill] call ended, got an exception 'std::future_error: Broken promise' during execution

